Workbook

Sheet info
B4: Vestas Sales Data — Data Ownership & Use Notice
B6: Copyright (c) Thomas Buhl. All rights reserved.
B8: I, Thomas Buhl, generated the dataset contained in this repository (“Data”) and I own the Data.
B10: Permission is granted to use the Data for personal, academic, and internal evaluation purposes, provided that you give appropriate credit to Thomas Buhl.
B12: Commercial use is not permitted without prior written permission. If you would like to use the Data for commercial purposes, please contact:
B13: thomasbuhldk@gmail.com
B16: DISCLAIMER
B17: THE DATA IS PROVIDED “AS IS”, WITHOUT WARRANTY OF ANY KIND, EXPRESS OR IMPLIED, INCLUDING BUT NOT LIMITED TO THE WARRANTIES OF ACCURACY, COMPLETENESS, NON-INFRINGEMENT, MERCHANTABILITY, OR FITNESS FOR A PARTICULAR PURPOSE.
B19: LIMITATION OF LIABILITY
B20: IN NO EVENT SHALL THOMAS BUHL BE LIABLE FOR ANY CLAIM, DAMAGES, OR OTHER LIABILITY, WHETHER IN AN ACTION OF CONTRACT, TORT, OR OTHERWISE, ARISING FROM, OUT OF, OR IN CONNECTION WITH THE DATA OR THE USE OR OTHER DEALINGS IN THE DATA. USE THE DATA AT YOUR OWN RISK.
B22: Unofficial dashboard — not affiliated with or endorsed by Vestas. Data compiled manually from public Vestas reports/announcements; verify against original sources. Provided “as is” without warranty.
B24: ## Sources and attribution
... B36: The data and dashboard are provided “as is” without warranties of any kind. I make no guarantees of accuracy, completeness, or fitness for a particular purpose. Use at your own risk. I am not responsible or liable for any losses or damages arising from use of the data or dashboard.

Sheet Vestas Economy
B1: 1995 | C1: 1996 | D1: 1997 | E1: 1998 | F1: 1999 | G1: 2000 | H1: 2001 | I1: 2002 | J1: 2003 | K1: 2004 | L1: 2005 | M1: 2006 | N1: 2007 | O1: 2008 | P1: 2009 | Q1: 2010 | R1: 2011 | S1: 2012 | T1: 2013 | U1: 2014 | V1: 2015 | W1: 2016 | X1: 2017 | Y1: 2018 | Z1: 2019 | AA1: 2020 | AB1: 2021 | AC1: 2022 | AD1: 2023 | AE1: 2024 | AF1: 2025
A2: revenue (mEUR) | C2: 252 | D2: 262 | E2: 379 | F2: 634 | G2: 896 | H2: 1282 | I2: 1395 | J2: 1653 | K2: 2363 | L2: 3583 | M2: 3854 | N2: 4861 | O2: 6035 | P2: 5079 | Q2: 6920 | R2: 5836 | S2: 7216 | T2: 6084 | U2: 6910 | V2: 8423 | W2: 10237 | X2: 9953 | Y2: 10134 | Z2: 12147 | AA2: 14819 | AB2: 15587 | AC2: 14486 | AD2: 15382 | AE2: 17295 | AF2: 18822
A3: gross profit | C3: 27 | D3: 32 | E3: 50 | F3: 69 | G3: 136 | H3: 192 | I3: 142 | J3: 150 | K3: 120 | L3: 84 | M3: 461 | N3: 825 | O3: 1125 | P3: 836 | Q3: 1175 | R3: 725 | S3: 796 | T3: 896 | U3: 1178 | V3: 1505 | W3: 2126 | X3: 1963 | Y3: 1631 | Z3: 1761 | AA3: 1538 | AB3: 1556 | AC3: 118 | AD3: 1283 | AE3: 2057 | AF3: 2497
A4: EBIT | C4: 15 | D4: 19 | E4: 32 | F4: 69 | G4: 100 | H4: 143 | I4: 74 | J4: 74 | K4: -49 | L4: -116 | M4: 201 | N4: 202 | O4: 614 | P4: 251 | Q4: 310 | R4: -60 | S4: -697 | T4: 102 | U4: 607 | V4: 906 | W4: 1421 | X4: 1230 | Y4: 921 | Z4: 1004 | AA4: 698 | AB4: 289 | AC4: -1596 | AD4: 292 | AE4: 794 | AF4: 1015
A5: sales of projects | K5: 2161 | L5: 3340 | M5: 3577 | N5: 4497 | O5: =5566+73 -> 5639 | P5: =6126+6 -> 6132 | Q5: =6283+14 -> 6297 | R5: =5115+16 -> 5131 | S5: =6298+32 -> 6330 | T5: =5082+48 -> 5130 | U5: 5946 | V5: 7285 | W5: 8928 | X5: =X2-X6 -> 8431 | Y5: 8465 | Z5: 10276 | AA5: 12764 | AB5: 13103 | AC5: 11331 | AD5: 11814 | AE5: 13598 | AF5: 15052
A6: sales of service | K6: 115 | L6: 172 | M6: 214 | N6: 298 | O6: 396 | P6: 504 | Q6: 623 | R6: 705 | S6: 886 | T6: 954 | U6: 964 | V6: 1138 | W6: 1309 | X6: 1522 | Y6: 1669 | Z6: 1871 | AA6: 2055 | AB6: 2484 | AC6: 3155 | AD6: 3568 | AE6: 3697 | AF6: 3770
A7: Order intake (bnEUR) | N7: 5.5 | O7: 6.4 | P7: 3.2 | Q7: 8.6 | R7: 7.3 | S7: 3.8 | T7: 5.8 | U7: 5.8 | V7: 8.2 | W7: 9.5 | X7: 8.9 | Y7: 10.6 | Z7: 13.8 | AA7: 12.7 | AB7: 11.6 | AC7: 11.9 | AD7: 18.5 | AE7: 19.2 | AF7: 17.4
A8: Order inkake (MW) | E8: 556 | F8: 1147 | G8: 1434 | H8: 2520 | I8: 2670 | J8: 2667 | K8: 2784 | L8: 3185 | M8: 4239 | N8: 5613 | O8: 6019 | P8: 3072 | Q8: 8673 | R8: 7397 | S8: 3738 | T8: 5964 | U8: 6544 | V8: 8943 | W8: 10494 | X8: 11237 | Y8: 14214 | Z8: 17877 | AA8: 17249 | AB8: 13896 | AC8: 11189 | AD8: 18286 | AE8: 16844 | AF8: 16292
A9: Order backlog – wind turbines (bnEUR) | N9: 4.8 | O9: 5.2 | P9: 2.2 | Q9: 7.7 | R9: 9.6 | S9: 7.1 | T9: 6.8 | U9: 6.7 | V9: 7.9 | W9: 8.5 | X9: 8.8 | Y9: 11.9 | Z9: 16 | AA9: 19 | AB9: 18.1 | AC9: 19.1 | AD9: 26 | AE9: 31.6 | AF9: 33.2
A10: Order backlog – service (bnEUR) | P10: 1.9 | Q10: 2.8 | R10: 3.9 | S10: 5.3 | T10: 6.7 | U10: 7 | V10: 8.9 | W10: 10.7 | X10: 12.1 | Y10: 14.3 | Z10: 17.8 | AA10: 23.9 | AB10: 27.8 | AC10: 30.4 | AD10: 34.1 | AE10: 36.8 | AF10: 38.7
A11: Order backlog - windturbines (MW) | X11: 11492 | Y11: 15646 | Z11: 20974 | AA11: 24630 | AB11: 21984 | AC11: 19623 | AD11: 25315 | AE11: 29241 | AF11: 31026
A13: WT order backlog/sold GW | N13: =1000*N9/N8 -> 0.85515767 | O13: =1000*O9/O8 -> 0.86393089 | P13: =1000*P9/P8 -> 0.71614583 | Q13: =1000*Q9/Q8 -> 0.88781275 | R13: =1000*R9/R8 -> 1.2978234 | S13: =1000*S9/S8 -> 1.8994114 | T13: =1000*T9/T8 -> 1.1401744 | U13: =1000*U9/U8 -> 1.0238386 | ... AF13: =1000*AF9/AF8 -> 2.03781
A14: Service order backlog/sold GW | P14: =1000*P10/P8 -> 0.61848958 | Q14: =1000*Q10/Q8 -> 0.322841 | R14: =1000*R10/R8 -> 0.52724077 | S14: =1000*S10/S8 -> 1.4178705 | T14: =1000*T10/T8 -> 1.1234071 | U14: =1000*U10/U8 -> 1.0696822 | V14: =1000*V10/V8 -> 0.99519177 | W14: =1000*W10/W8 -> 1.0196303 | ... AF14: =1000*AF10/AF8 -> 2.375399
A15: Produced and shipped wind turbine (MW) | F15: 653 | G15: 805 | H15: 1645 | I15: 1640 | J15: 1812 | L15: 3900 | M15: 4313 | N15: 4974 | O15: 6160 | P15: 6131 | Q15: 4057 | R15: 5054 | S15: 6171 | T15: 4513 | U15: 6125 | V15: 7948 | W15: 11237 | X15: 11237 | Y15: 10676 | Z15: 12618 | AA15: 17055 | AB15: 17845 | AC15: 13106 | AD15: 11666 | AE15: 13198 | AF15: 13374
A16: Produced and shipped wind turbine (#) | F16: 843 | G16: 1014 | H16: 1970 | I16: 1453 | J16: 1369 | M16: 2553 | N16: 2752 | O16: 3250 | P16: 3320 | Q16: 2025 | R16: 2571 | S16: 2765 | T16: 2025 | U16: 2527 | V16: 3330 | W16: 4264 | X16: 4241 | Y16: 3729 | Z16: 4185 | AA16: 5239 | AB16: 4456 | AC16: 3126 | AD16: 2554 | AE16: 2837 | AF16: 2737
A17: deliveries [MW] | Z17: 12884 | AA17: 17212 | AB17: 16594 | AC17: 13328 | AD17: 12685 | AE17: 12900 | AF17: 14537
A19: employees:
A20: Manufacturing and sourcing | L20: 6338 | O20: 11166 | R20: 11000 | S20: 7528 | T20: 6430 | U20: 10092 | V20: 10282 | W20: 10112
A21: sales | L21: 3341 | O21: 7143 | R21: 7681 | S21: 6187 | T21: 5869 | U21: 6214 | V21: 7682 | W21: 8956
A22: Technology and Service (R&D) | O22: 1345 | R22: 2037 | S22: 2142 | T22: 1797 | U22: 1265 | V22: 1292 | W22: 1414
A23: Others | L23: 939 | O23: 1175 | R23: 2003 | S23: 1921 | T23: 1401 | U23: 2098 | V23: 1251 | W23: 1342
A25: Material comsumption
A26: Metals | I26: 61113 | J26: 66093 | K26: 90732 | L26: 143170 | M26: 164413 | N26: 170505 | O26: 187478 | P26: 202624 | Q26: 171000 | R26: 212000 | S26: 192000 | T26: 119000
A27: Other raw materials | I27: 15428 | J27: 15731 | K27: 20080 | L27: 82592 | M27: 93983 | N27: 111541 | O27: 129207 | P27: 126600 | Q27: 107000 | R27: 105000 | S27: 121000 | T27: 91000
A28: Waste of on operation [kt] | Z28: 85 | AA28: 89 | AB28: 70 | AC28: 47 | AD28: 44 | AE28: 44 | AF28: 54
A29: of which recycled [kt] | Z29: 43 | AA29: 46 | AB29: 35 | AC29: 26 | AD29: 30 | AE29: 30 | AF29: =0.69*AF28 -> 37.26
A30: Material effeciency - t waste pr MW shipped | Z30: 3.3 | AA30: 2.5 | AB30: 2 | AC30: 1.6 | AD30: 1.2 | AE30: 1 | AF30: 1.3
A31: Consumption of energy (GWh) | AA31: 621 | AB31: 738 | AC31: 641 | AD31: 658 | AE31: 640 | AF31: 677
A33: average # employees | C33: 1108 | D33: 1206 | E33: 1477 | F33: 2261 | G33: 3282 | H33: 4582 | I33: 5974 | J33: 6394 | K33: 9449 | L33: 10300 | M33: 11334 | N33: 13820 | O33: 17924 | P33: 20832 | Q33: 22216 | R33: 22926 | S33: 21033 | T33: 17051 | U33: 17905 | V33: 18986 | W33: 21625 | X33: 22504 | Y33: 24221 | Z33: 24964 | AA33: 26121 | AB33: 29164 | AC33: 28779 | AD33: 29463 | AE33: 32729
A34: EOY employees | E34: 1813 | F34: 2626 | G34: 3852 | H34: 5240 | I34: 5999 | J34: 6525 | K34: 9594 | L34: 10618 | M34: 12309 | N34: 15305 | O34: 20829 | P34: 20730 | Q34: 23252 | R34: 22721 | S34: 17778 | T34: 15497 | U34: 19669 | V34: 20507 | W34: 21824 | X34: 23303 | Y34: 24648 | Z34: 25542 | AA34: 29378 | AB34: 29427 | AC34: 28438 | AD34: 30586 | AE34: 35100 | AF34: 36973
A36: Turbine sale index | O36: 100 | P36: =P5/$O5*100 -> 108.74268 | Q36: =Q5/$O5*100 -> 111.66874 | R36: =R5/$O5*100 -> 90.991311 | S36: =S5/$O5*100 -> 112.25395 | T36: =T5/$O5*100 -> 90.973577 | U36: =U5/$O5*100 -> 105.44423 | V36: =V5/$O5*100 -> 129.18957 | W36: =W5/$O5*100 -> 158.32594 | ... AF36: =AF5/$O5*100 -> 266.92676
A37: Service sale index | O37: 100 | P37: =P6/$O6*100 -> 127.27273 | Q37: =Q6/$O6*100 -> 157.32323 | R37: =R6/$O6*100 -> 178.0303 | S37: =S6/$O6*100 -> 223.73737 | T37: =T6/$O6*100 -> 240.90909 | U37: =U6/$O6*100 -> 243.43434 | V37: =V6/$O6*100 -> 287.37374 | W37: =W6/$O6*100 -> 330.55556 | ... AF37: =AF6/$O6*100 -> 952.0202
A39: average MW price [mEUR/MW] | N39: =1000*N7/N8 -> 0.97986816 | O39: =1000*O7/O8 -> 1.0632996 | P39: =1000*P7/P8 -> 1.0416667 | Q39: =1000*Q7/Q8 -> 0.99158307 | R39: =1000*R7/R8 -> 0.98688658 | S39: =1000*S7/S8 -> 1.0165864 | T39: =1000*T7/T8 -> 0.97250168 | U39: =1000*U7/U8 -> 0.88630807 | ... AF39: =1000*AF7/AF8 -> 1.0680088
A40: In % | O40: =O39/$O$39 -> 1 | P40: =P39/$O$39 -> 0.97965495 | Q40: =Q39/$O$39 -> 0.93255289 | R40: =R39/$O$39 -> 0.92813598 | S40: =S39/$O$39 -> 0.95606775 | T40: =T39/$O$39 -> 0.91460744 | U40: =U39/$O$39 -> 0.83354504 | V40: =V39/$O$39 -> 0.86233297 | ... AF40: =AF39/$O$39 -> 1.0044289
A42: Weighted average service contract lenght | W42: ='OI 2016'!E125 -> 5.6366513 | X42: ='OI 2017'!E155 -> 2.3568755 | Y42: ='OI 2018'!E155 -> 10.306983 | Z42: ='OI 2019'!E156 -> 12.122227 | AA42: ='OI 2020'!E187 -> 14.699832 | AB42: ='OI 2021'!E189 -> 5.3373273
C45: Servicemargin | D45: Samlet margin | E45: Margin eksl. service
A46: 16Q1 | C46: 17.4 | D46: 5.8 | E46: 2.83
A47: 16Q2 | C47: 17.8 | D47: 15.6 | E47: 15.28
A48: 16Q3 | C48: 14.1 | D48: 14.9 | E48: 15.01
A49: 16Q4 | C49: 19.1 | D49: 15.2 | E49: 14.72
...

Sheet Order and Service summary
E1: If model is specified | V1: Size | AG1: MW of each service
C2: Turbine model of platform | D2: 2014 | E2: 2015 | F2: 2016 | G2: 2017 | H2: 2018 | I2: 2019 | J2: 2020 | K2: 2021 | L2: 2022 | M2: 2023 | N2: 2024 | O2: 2025 | R2: 2012 | S2: 2013 | T2: 2014 | U2: 2015 | V2: 2016 | W2: 2017 | X2: 2018 | Y2: 2019 | Z2: 2020 | AA2: 2021 | AB2: 2022 | AC2: 2023 | AF2: 2014 | AG2: 2015 | AH2: 2016 | AI2: 2017 | AJ2: 2018 | AK2: 2019 | AL2: 2020
C3: 2MW | D3: =SUMIF('OI 2014'!$I$87:$I$101,C3,'OI 2014'!$L$87:$L$101) -> 30 | E3: =SUMIF('OI 2015'!$I$87:$I$101,C3,'OI 2015'!$L$87:$L$101) -> 75 | F3: =SUMIF('OI 2016'!$I$87:$I$101,C3,'OI 2016'!$L$87:$L$101) -> 184.6 | G3: =SUMIF('OI 2017'!$I$112:$I$128,C3,'OI 2017'!$L$112:$L$128) -> 175 | H3: =SUMIF('OI 2018'!$I$112:$I$131,C3,'OI 2018'!$L$112:$L$131) -> 100 | I3: =SUMIF('OI 2019'!$I$113:$I$132,C3,'OI 2019'!$L$113:$L$132) -> 0 | J3: =SUMIF('OI 2020'!$I$144:$I$165,C3,'OI 2020'!$K$144:$K$165) -> 0 | K3: =SUMIF('OI 2021'!$I$145:$I$166,C3,'OI 2021'!$K$145:$K$166) -> 0 | L3: =SUMIF('OI 2022'!$I$158:$I$175,$C3,'OI 2022'!$K$158:$K$175) -> 0 | M3: =SUMIF('OI 2023'!$I$158:$I$173,$C3,'OI 2023'!$J$158:$J$173) -> 0 | Q3: >2MW | R3: ='OI 2012'!M78+'OI 2012'!T78 -> 163 | S3: ='OI 2013'!M78+'OI 2013'!T78 -> 229.91111 | T3: ='OI 2014'!M78+'OI 2014'!T78 -> 364.70588 | U3: ='OI 2015'!M78+'OI 2015'!T78 -> 70 | V3: ='OI 2016'!M78+'OI 2016'!T78 -> 15 | W3: 0 | X3: 0 | Y3: 0 | Z3: 0 | AA3: 0 | AB3: 0 | AC3: 0 | AE3: AOM4000 | AF3: ='OI 2014'!E81 -> 1234 | AG3: ='OI 2015'!E81 -> 2363 | AH3: ='OI 2016'!E81 -> 1849 | AI3: ='OI 2017'!E106 -> 1785 | AJ3: ='OI 2018'!E106 -> 1202.8 | AK3: ='OI 2019'!E107 -> 2214 | AL3: ='OI 2020'!E138 -> 2087
C4: 3MW | D4: =SUMIF('OI 2014'!$I$87:$I$101,C4,'OI 2014'!$L$87:$L$101) -> 0 | E4: =SUMIF('OI 2015'!$I$87:$I$101,C4,'OI 2015'!$L$87:$L$101) -> 0 | F4: =SUMIF('OI 2016'!$I$87:$I$101,C4,'OI 2016'!$L$87:$L$101) -> 26 | G4: =SUMIF('OI 2017'!$I$112:$I$128,C4,'OI 2017'!$L$112:$L$128) -> 0 | H4: =SUMIF('OI 2018'!$I$112:$I$131,C4,'OI 2018'!$L$112:$L$131) -> 0 | I4: =SUMIF('OI 2019'!$I$113:$I$132,C4,'OI 2019'!$L$113:$L$132) -> 0 | J4: =SUMIF('OI 2020'!$I$144:$I$165,C4,'OI 2020'!$K$144:$K$165) -> 0 | K4: =SUMIF('OI 2021'!$I$145:$I$166,C4,'OI 2021'!$K$145:$K$166) -> 0 | L4: =SUMIF('OI 2022'!$I$158:$I$175,$C4,'OI 2022'!$K$158:$K$175) -> 0 | M4: =SUMIF('OI 2023'!$I$158:$I$173,$C4,'OI 2023'!$J$158:$J$173) -> 0 | Q4: 2-2.99MW | R4: ='OI 2012'!M79+'OI 2012'!T79 -> 237 | S4: ='OI 2013'!M79+'OI 2013'!T79 -> 1123.7 | T4: ='OI 2014'!M79+'OI 2014'!T79 -> 1080 | U4: ='OI 2015'!M79+'OI 2015'!T79 -> 1470 | V4: ='OI 2016'!M79+'OI 2016'!T79 -> 1642.9636 | W4: ='OI 2017'!M103+'OI 2017'!T103 -> 1729.8636 | X4: ='OI 2018'!M103+'OI 2018'!T103 -> 1460 | Y4: ='OI 2019'!N104+'OI 2019'!V104 -> 1590.8182 | Z4: ='OI 2020'!M135 -> 723 | AA4: ='OI 2021'!N137 -> 1008 | AB4: ='OI 2022'!N149 -> 224 | AC4: ='OI 2023'!N149 -> 806 | AE4: AOM5000 | AF4: ='OI 2014'!E80 -> 2559 | AG4: ='OI 2015'!E80 -> 3421 | AH4: ='OI 2016'!E80 -> 3190 | AI4: ='OI 2017'!E105 -> 4551 | AJ4: ='OI 2018'!E105 -> 7360.4 | AK4: ='OI 2019'!E106 -> 6601 | AL4: ='OI 2020'!E137 -> 9504
C5: 4MW | D5: =SUMIF('OI 2014'!$I$87:$I$101,C5,'OI 2014'!$L$87:$L$101) -> 0 | E5: =SUMIF('OI 2015'!$I$87:$I$101,C5,'OI 2015'!$L$87:$L$101) -> 0 | F5: =SUMIF('OI 2016'!$I$87:$I$101,C5,'OI 2016'!$L$87:$L$101) -> 0 | G5: =SUMIF('OI 2017'!$I$112:$I$128,C5,'OI 2017'!$L$112:$L$128) -> 79.5 | H5: =SUMIF('OI 2018'!$I$112:$I$131,C5,'OI 2018'!$L$112:$L$131) -> 20.25 | I5: =SUMIF('OI 2019'!$I$113:$I$132,C5,'OI 2019'!$L$113:$L$132) -> 0 | J5: =SUMIF('OI 2020'!$I$144:$I$165,C5,'OI 2020'!$K$144:$K$165) -> 0 | K5: =SUMIF('OI 2021'!$I$145:$I$166,C5,'OI 2021'!$K$145:$K$166) -> 12 | L5: =SUMIF('OI 2022'!$I$158:$I$175,$C5,'OI 2022'!$K$158:$K$175) -> 0 | M5: =SUMIF('OI 2023'!$I$158:$I$173,$C5,'OI 2023'!$J$158:$J$173) -> 0 | Q5: 3-3.99MW | R5: ='OI 2012'!M80+'OI 2012'!T80 -> 323 | S5: ='OI 2013'!M80+'OI 2013'!T80 -> 511.89091 | T5: ='OI 2014'!M80+'OI 2014'!T80 -> 481.48485 | U5: ='OI 2015'!M80+'OI 2015'!T80 -> 1081.9379 | V5: ='OI 2016'!M80+'OI 2016'!T80 -> 1136.6096 | W5: ='OI 2017'!M104+'OI 2017'!T104 -> 1261.2067 | X5: ='OI 2018'!M104+'OI 2018'!T104 -> 1311.9335 | Y5: ='OI 2019'!N105+'OI 2019'!V105 -> 429.33816 | Z5: ='OI 2020'!N136 -> 2485 | AA5: ='OI 2021'!N138 -> 811 | AB5: ='OI 2022'!N150 -> 123 | AC5: ='OI 2023'!N150 -> 130
C6: V52-850kW | D6: =SUMIF('OI 2014'!$I$87:$I$101,C6,'OI 2014'!$L$87:$L$101) -> 364.70588 | E6: =SUMIF('OI 2015'!$I$87:$I$101,C6,'OI 2015'!$L$87:$L$101) -> 0 | F6: =SUMIF('OI 2016'!$I$87:$I$101,C6,'OI 2016'!$L$87:$L$101) -> 0 | G6: =SUMIF('OI 2017'!$I$112:$I$128,C6,'OI 2017'!$L$112:$L$128) -> 0 | H6: =SUMIF('OI 2018'!$I$112:$I$131,C6,'OI 2018'!$L$112:$L$131) -> 0 | I6: =SUMIF('OI 2019'!$I$113:$I$132,C6,'OI 2019'!$L$113:$L$132) -> 0 | J6: =SUMIF('OI 2020'!$I$144:$I$165,C6,'OI 2020'!$K$144:$K$165) -> 0 | K6: =SUMIF('OI 2021'!$I$145:$I$166,C6,'OI 2021'!$K$145:$K$166) -> 0 | L6: =SUMIF('OI 2022'!$I$158:$I$175,$C6,'OI 2022'!$K$158:$K$175) -> 0 | M6: =SUMIF('OI 2023'!$I$158:$I$173,$C6,'OI 2023'!$J$158:$J$173) -> 0 | Q6: 4-5.99MW | R6: 0 | S6: 0 | T6: ='OI 2014'!M81+'OI 2014'!T81 -> 0 | U6: ='OI 2015'!M81+'OI 2015'!T81 -> 0 | V6: ='OI 2016'!M81+'OI 2016'!T81 -> 0 | W6: ='OI 2017'!M105+'OI 2017'!T105 -> 164.5 | X6: ='OI 2018'!M105+'OI 2018'!T105 -> 725.05952 | Y6: ='OI 2019'!N106+'OI 2019'!V106 -> 1435.7674 | Z6: ='OI 2020'!N137 -> 7134 | AA6: ='OI 2021'!N139 -> 4446 | AB6: ='OI 2022'!N151 -> 4962 | AC6: ='OI 2023'!N151 -> 9281
C7: V80-2.0MW | D7: =SUMIF('OI 2014'!$I$87:$I$101,C7,'OI 2014'!$L$87:$L$101) -> 34 | E7: =SUMIF('OI 2015'!$I$87:$I$101,C7,'OI 2015'!$L$87:$L$101) -> 0 | F7: =SUMIF('OI 2016'!$I$87:$I$101,C7,'OI 2016'!$L$87:$L$101) -> 0 | G7: =SUMIF('OI 2017'!$I$112:$I$128,C7,'OI 2017'!$L$112:$L$128) -> 0 | H7: =SUMIF('OI 2018'!$I$112:$I$131,C7,'OI 2018'!$L$112:$L$131) -> 0 | I7: =SUMIF('OI 2019'!$I$113:$I$132,C7,'OI 2019'!$L$113:$L$132) -> 0 | J7: =SUMIF('OI 2020'!$I$144:$I$165,C7,'OI 2020'!$K$144:$K$165) -> 0 | K7: =SUMIF('OI 2021'!$I$145:$I$166,C7,'OI 2021'!$K$145:$K$166) -> 0 | L7: =SUMIF('OI 2022'!$I$158:$I$175,$C7,'OI 2022'!$K$158:$K$175) -> 0 | M7: =SUMIF('OI 2023'!$I$158:$I$173,$C7,'OI 2023'!$J$158:$J$173) -> 0 | Q7: 6-7MW | Z7: ='OI 2020'!N138 -> 1313 | AA7: ='OI 2021'!N140 -> 3284 | AB7: ='OI 2022'!N152 -> 2588 | AC7: ='OI 2023'!N152 -> 1937 | AG7: MW of each service
C8: V90-2.0MW | D8: =SUMIF('OI 2014'!$I$87:$I$101,C8,'OI 2014'!$L$87:$L$101) -> 21 | E8: =SUMIF('OI 2015'!$I$87:$I$101,C8,'OI 2015'!$L$87:$L$101) -> 49 | F8: =SUMIF('OI 2016'!$I$87:$I$101,C8,'OI 2016'!$L$87:$L$101) -> 0 | G8: =SUMIF('OI 2017'!$I$112:$I$128,C8,'OI 2017'!$L$112:$L$128) -> 0 | H8: =SUMIF('OI 2018'!$I$112:$I$131,C8,'OI 2018'!$L$112:$L$131) -> 0 | I8: =SUMIF('OI 2019'!$I$113:$I$132,C8,'OI 2019'!$L$113:$L$132) -> 0 | J8: =SUMIF('OI 2020'!$I$144:$I$165,C8,'OI 2020'!$K$144:$K$165) -> 1 | K8: =SUMIF('OI 2021'!$I$145:$I$166,C8,'OI 2021'!$K$145:$K$166) -> 2 | L8: =SUMIF('OI 2022'!$I$158:$I$175,$C8,'OI 2022'!$K$158:$K$175) -> 0 | M8: =SUMIF('OI 2023'!$I$158:$I$173,$C8,'OI 2023'!$J$158:$J$173) -> 0 | Q8: 7+ | AA8: ='OI 2021'!N141 -> 733 | AB8: ='OI 2022'!N153 -> 650 | AC8: ='OI 2023'!N153 -> 3168 | AF8: 2014 | AG8: 2015 | AH8: 2016 | AI8: 2017 | AJ8: 2018 | AK8: 2019 | AL8: 2020
C9: V90-3.0MW | D9: =SUMIF('OI 2014'!$I$87:$I$101,C9,'OI 2014'!$L$87:$L$101) -> 61 | E9: =SUMIF('OI 2015'!$I$87:$I$101,C9,'OI 2015'!$L$87:$L$101) -> 29 | F9: =SUMIF('OI 2016'!$I$87:$I$101,C9,'OI 2016'!$L$87:$L$101) -> 40 | G9: =SUMIF('OI 2017'!$I$112:$I$128,C9,'OI 2017'!$L$112:$L$128) -> 0 | H9: =SUMIF('OI 2018'!$I$112:$I$131,C9,'OI 2018'!$L$112:$L$131) -> 0 | I9: =SUMIF('OI 2019'!$I$113:$I$132,C9,'OI 2019'!$L$113:$L$132) -> 0 | J9: =SUMIF('OI 2020'!$I$144:$I$165,C9,'OI 2020'!$K$144:$K$165) -> 0 | K9: =SUMIF('OI 2021'!$I$145:$I$166,C9,'OI 2021'!$K$145:$K$166) -> 0 | L9: =SUMIF('OI 2022'!$I$158:$I$175,$C9,'OI 2022'!$K$158:$K$175) -> 0 | M9: =SUMIF('OI 2023'!$I$158:$I$173,$C9,'OI 2023'!$J$158:$J$173) -> 0 | AE9: AOM2000 | AI9: 1.3 | AJ9: 0.7
C10: V100-1.8MW | D10: =SUMIF('OI 2014'!$I$87:$I$101,C10,'OI 2014'!$L$87:$L$101) -> 0 | E10: =SUMIF('OI 2015'!$I$87:$I$101,C10,'OI 2015'!$L$87:$L$101) -> 70 | F10: =SUMIF('OI 2016'!$I$87:$I$101,C10,'OI 2016'!$L$87:$L$101) -> 15 | G10: =SUMIF('OI 2017'!$I$112:$I$128,C10,'OI 2017'!$L$112:$L$128) -> 0 | H10: =SUMIF('OI 2018'!$I$112:$I$131,C10,'OI 2018'!$L$112:$L$131) -> 0 | I10: =SUMIF('OI 2019'!$I$113:$I$132,C10,'OI 2019'!$L$113:$L$132) -> 0 | J10: =SUMIF('OI 2020'!$I$144:$I$165,C10,'OI 2020'!$K$144:$K$165) -> 0 | K10: =SUMIF('OI 2021'!$I$145:$I$166,C10,'OI 2021'!$K$145:$K$166) -> 0 | L10: =SUMIF('OI 2022'!$I$158:$I$175,$C10,'OI 2022'!$K$158:$K$175) -> 0 | M10: =SUMIF('OI 2023'!$I$158:$I$173,$C10,'OI 2023'!$J$158:$J$173) -> 0 | Q10: sum #WTG | R10: =SUM(R3:R7) -> 723 | S10: =SUM(S3:S7) -> 1865.502 | T10: =SUM(T3:T7) -> 1926.1907 | U10: =SUM(U3:U7) -> 2621.9379 | V10: =SUM(V3:V7) -> 2794.5732 | W10: =SUM(W3:W7) -> 3155.5704 | X10: =SUM(X3:X7) -> 3496.993 | Y10: =SUM(Y3:Y7) -> 3455.9238 | AE10: AOM3000 | AI10: 3.4 | AJ10: 6.9
C11: V100-2.0MW | D11: =SUMIF('OI 2014'!$I$87:$I$101,C11,'OI 2014'!$L$87:$L$101) -> 659 | E11: =SUMIF('OI 2015'!$I$87:$I$101,C11,'OI 2015'!$L$87:$L$101) -> 486 | F11: =SUMIF('OI 2016'!$I$87:$I$101,C11,'OI 2016'!$L$87:$L$101) -> 104 | G11: =SUMIF('OI 2017'!$I$112:$I$128,C11,'OI 2017'!$L$112:$L$128) -> 72 | H11: =SUMIF('OI 2018'!$I$112:$I$131,C11,'OI 2018'!$L$112:$L$131) -> 141 | I11: =SUMIF('OI 2019'!$I$113:$I$132,C11,'OI 2019'!$L$113:$L$132) -> 0 | J11: =SUMIF('OI 2020'!$I$144:$I$165,C11,'OI 2020'!$K$144:$K$165) -> 124 | K11: =SUMIF('OI 2021'!$I$145:$I$166,C11,'OI 2021'!$K$145:$K$166) -> 86 | L11: =SUMIF('OI 2022'!$I$158:$I$175,$C11,'OI 2022'!$K$158:$K$175) -> 2 | M11: =SUMIF('OI 2023'!$I$158:$I$173,$C11,'OI 2023'!$J$158:$J$173) -> 40 | Q11: sum MW | R11: ='OI 2012'!E78 -> 2281.8 | S11: ='OI 2013'!E78 -> 4325 | T11: ='OI 2014'!E78 -> 4112 | U11: ='OI 2015'!E78 -> 6753 | V11: ='OI 2016'!E78 -> 7585 | W11: ='OI 2017'!E103 -> 13165 | X11: ='OI 2018'!E103 -> 15473.2 | Y11: ='OI 2019'!E104 -> 17862 | AE11: AOM4000 | AF11: =AF3/(AF3+AF4) -> 0.32533615 | AG11: =AG3/(AG3+AG4) -> 0.4085408 | AH11: =AH3/(AH3+AH4) -> 0.36693788 | AI11: 0.337 | AJ11: 0.328
C12: V105-3.45MW | D12: =SUMIF('OI 2014'!$I$87:$I$101,C12,'OI 2014'!$L$87:$L$101) -> 0 | E12: =SUMIF('OI 2015'!$I$87:$I$101,C12,'OI 2015'!$L$87:$L$101) -> 0 | F12: =SUMIF('OI 2016'!$I$87:$I$101,C12,'OI 2016'!$L$87:$L$101) -> 8.9855072 | G12: =SUMIF('OI 2017'!$I$112:$I$128,C12,'OI 2017'!$L$112:$L$128) -> 31.714976 | H12: =SUMIF('OI 2018'!$I$112:$I$131,C12,'OI 2018'!$L$112:$L$131) -> 0 | I12: =SUMIF('OI 2019'!$I$113:$I$132,C12,'OI 2019'!$L$113:$L$132) -> 17 | J12: =SUMIF('OI 2020'!$I$144:$I$165,C12,'OI 2020'!$K$144:$K$165) -> 127 | K12: =SUMIF('OI 2021'!$I$145:$I$166,C12,'OI 2021'!$K$145:$K$166) -> 25 | L12: =SUMIF('OI 2022'!$I$158:$I$175,$C12,'OI 2022'!$K$158:$K$175) -> 8 | M12: =SUMIF('OI 2023'!$I$158:$I$173,$C12,'OI 2023'!$J$158:$J$173) -> 0 | AE12: AOM5000 | AF12: =AF4/(AF4+AF3) -> 0.67466385 | AG12: =AG4/(AG4+AG3) -> 0.5914592 | AH12: =AH4/(AH4+AH3) -> 0.63306212 | AI12: 0.616 | AJ12: 0.616
C13: V105-3.6MW | D13: =SUMIF('OI 2014'!$I$87:$I$101,C13,'OI 2014'!$L$87:$L$101) -> 0 | E13: =SUMIF('OI 2015'!$I$87:$I$101,C13,'OI 2015'!$L$87:$L$101) -> 0 | F13: =SUMIF('OI 2016'!$I$87:$I$101,C13,'OI 2016'!$L$87:$L$101) -> 0 | G13: =SUMIF('OI 2017'!$I$112:$I$128,C13,'OI 2017'!$L$112:$L$128) -> 0 | H13: =SUMIF('OI 2018'!$I$112:$I$131,C13,'OI 2018'!$L$112:$L$131) -> 0 | I13: =SUMIF('OI 2019'!$I$113:$I$132,C13,'OI 2019'!$L$113:$L$132) -> 0 | J13: =SUMIF('OI 2020'!$I$144:$I$165,C13,'OI 2020'!$K$144:$K$165) -> 11 | K13: =SUMIF('OI 2021'!$I$145:$I$166,C13,'OI 2021'!$K$145:$K$166) -> 0 | L13: =SUMIF('OI 2022'!$I$158:$I$175,$C13,'OI 2022'!$K$158:$K$175) -> 0 | M13: =SUMIF('OI 2023'!$I$158:$I$173,$C13,'OI 2023'!$J$158:$J$173) -> 0
C14: V110-2.0MW | D14: =SUMIF('OI 2014'!$I$87:$I$101,C14,'OI 2014'!$L$87:$L$101) -> 336 | E14: =SUMIF('OI 2015'!$I$87:$I$101,C14,'OI 2015'!$L$87:$L$101) -> 860 | F14: =SUMIF('OI 2016'!$I$87:$I$101,C14,'OI 2016'!$L$87:$L$101) -> 1354.3636 | G14: =SUMIF('OI 2017'!$I$112:$I$128,C14,'OI 2017'!$L$112:$L$128) -> 1409.5 | H14: =SUMIF('OI 2018'!$I$112:$I$131,C14,'OI 2018'!$L$112:$L$131) -> 360.09091 | I14: =SUMIF('OI 2019'!$I$113:$I$132,C14,'OI 2019'!$L$113:$L$132) -> 255 | J14: =SUMIF('OI 2020'!$I$144:$I$165,C14,'OI 2020'!$K$144:$K$165) -> 215 | K14: =SUMIF('OI 2021'!$I$145:$I$166,C14,'OI 2021'!$K$145:$K$166) -> 59 | L14: =SUMIF('OI 2022'!$I$158:$I$175,$C14,'OI 2022'!$K$158:$K$175) -> 0 | M14: =SUMIF('OI 2023'!$I$158:$I$173,$C14,'OI 2023'!$J$158:$J$173) -> 259
C15: V110-2.2MW | D15: =SUMIF('OI 2014'!$I$87:$I$101,C15,'OI 2014'!$L$87:$L$101) -> 0 | E15: =SUMIF('OI 2015'!$I$87:$I$101,C15,'OI 2015'!$L$87:$L$101) -> 0 | F15: =SUMIF('OI 2016'!$I$87:$I$101,C15,'OI 2016'!$L$87:$L$101) -> 0 | G15: =SUMIF('OI 2017'!$I$112:$I$128,C15,'OI 2017'!$L$112:$L$128) -> 40.363636 | H15: =SUMIF('OI 2018'!$I$112:$I$131,C15,'OI 2018'!$L$112:$L$131) -> 183.18182 | I15: =SUMIF('OI 2019'!$I$113:$I$132,C15,'OI 2019'!$L$113:$L$132) -> 66 | J15: =SUMIF('OI 2020'!$I$144:$I$165,C15,'OI 2020'!$K$144:$K$165) -> 63 | K15: =SUMIF('OI 2021'!$I$145:$I$166,C15,'OI 2021'!$K$145:$K$166) -> 60.090909 | L15: =SUMIF('OI 2022'!$I$158:$I$175,$C15,'OI 2022'!$K$158:$K$175) -> 66 | M15: =SUMIF('OI 2023'!$I$158:$I$173,$C15,'OI 2023'!$J$158:$J$173) -> 0
C16: V112-3.075MW | D16: =SUMIF('OI 2014'!$I$87:$I$101,C16,'OI 2014'!$L$87:$L$101) -> 0 | E16: =SUMIF('OI 2015'!$I$87:$I$101,C16,'OI 2015'!$L$87:$L$101) -> 13.00813 | F16: =SUMIF('OI 2016'!$I$87:$I$101,C16,'OI 2016'!$L$87:$L$101) -> 0 | G16: =SUMIF('OI 2017'!$I$112:$I$128,C16,'OI 2017'!$L$112:$L$128) -> 0 | H16: =SUMIF('OI 2018'!$I$112:$I$131,C16,'OI 2018'!$L$112:$L$131) -> 0 | I16: =SUMIF('OI 2019'!$I$113:$I$132,C16,'OI 2019'!$L$113:$L$132) -> 0 | J16: =SUMIF('OI 2020'!$I$144:$I$165,C16,'OI 2020'!$K$144:$K$165) -> 0 | K16: =SUMIF('OI 2021'!$I$145:$I$166,C16,'OI 2021'!$K$145:$K$166) -> 0 | L16: =SUMIF('OI 2022'!$I$158:$I$175,$C16,'OI 2022'!$K$158:$K$175) -> 0 | M16: =SUMIF('OI 2023'!$I$158:$I$173,$C16,'OI 2023'!$J$158:$J$173) -> 0
C17: V112-3.0MW | D17: =SUMIF('OI 2014'!$I$87:$I$101,C17,'OI 2014'!$L$87:$L$101) -> 97.333333 | E17: =SUMIF('OI 2015'!$I$87:$I$101,C17,'OI 2015'!$L$87:$L$101) -> 12 | F17: =SUMIF('OI 2016'!$I$87:$I$101,C17,'OI 2016'!$L$87:$L$101) -> 0 | G17: =SUMIF('OI 2017'!$I$112:$I$128,C17,'OI 2017'!$L$112:$L$128) -> 0 | H17: =SUMIF('OI 2018'!$I$112:$I$131,C17,'OI 2018'!$L$112:$L$131) -> 19 | I17: =SUMIF('OI 2019'!$I$113:$I$132,C17,'OI 2019'!$L$113:$L$132) -> 0 | J17: =SUMIF('OI 2020'!$I$144:$I$165,C17,'OI 2020'!$K$144:$K$165) -> 0 | K17: =SUMIF('OI 2021'!$I$145:$I$166,C17,'OI 2021'!$K$145:$K$166) -> 0 | L17: =SUMIF('OI 2022'!$I$158:$I$175,$C17,'OI 2022'!$K$158:$K$175) -> 0 | M17: =SUMIF('OI 2023'!$I$158:$I$173,$C17,'OI 2023'!$J$158:$J$173) -> 0
C18: V112-3.3MW | D18: =SUMIF('OI 2014'!$I$87:$I$101,C18,'OI 2014'!$L$87:$L$101) -> 200.06061 | E18: =SUMIF('OI 2015'!$I$87:$I$101,C18,'OI 2015'!$L$87:$L$101) -> 212.12121 | F18: =SUMIF('OI 2016'!$I$87:$I$101,C18,'OI 2016'!$L$87:$L$101) -> 34.848485 | G18: =SUMIF('OI 2017'!$I$112:$I$128,C18,'OI 2017'!$L$112:$L$128) -> 26.060606 | H18: =SUMIF('OI 2018'!$I$112:$I$131,C18,'OI 2018'!$L$112:$L$131) -> 0 | I18: =SUMIF('OI 2019'!$I$113:$I$132,C18,'OI 2019'!$L$113:$L$132) -> 9 | J18: =SUMIF('OI 2020'!$I$144:$I$165,C18,'OI 2020'!$K$144:$K$165) -> 0 | K18: =SUMIF('OI 2021'!$I$145:$I$166,C18,'OI 2021'!$K$145:$K$166) -> 0 | L18: =SUMIF('OI 2022'!$I$158:$I$175,$C18,'OI 2022'!$K$158:$K$175) -> 0 | M18: =SUMIF('OI 2023'!$I$158:$I$173,$C18,'OI 2023'!$J$158:$J$173) -> 0
C19: V112-3.45MW | D19: =SUMIF('OI 2014'!$I$87:$I$101,C19,'OI 2014'!$L$87:$L$101) -> 0 | E19: =SUMIF('OI 2015'!$I$87:$I$101,C19,'OI 2015'!$L$87:$L$101) -> 140.69652 | F19: =SUMIF('OI 2016'!$I$87:$I$101,C19,'OI 2016'!$L$87:$L$101) -> 164.15942 | G19: =SUMIF('OI 2017'!$I$112:$I$128,C19,'OI 2017'!$L$112:$L$128) -> 40.125604 | H19: =SUMIF('OI 2018'!$I$112:$I$131,C19,'OI 2018'!$L$112:$L$131) -> 22.951252 | I19: =SUMIF('OI 2019'!$I$113:$I$132,C19,'OI 2019'!$L$113:$L$132) -> 72 | J19: =SUMIF('OI 2020'!$I$144:$I$165,C19,'OI 2020'!$K$144:$K$165) -> 34 | K19: =SUMIF('OI 2021'!$I$145:$I$166,C19,'OI 2021'!$K$145:$K$166) -> 10 | L19: =SUMIF('OI 2022'!$I$158:$I$175,$C19,'OI 2022'!$K$158:$K$175) -> 2 | M19: =SUMIF('OI 2023'!$I$158:$I$173,$C19,'OI 2023'!$J$158:$J$173) -> 0
C20: V116-2.0MW | D20: =SUMIF('OI 2014'!$I$87:$I$101,C20,'OI 2014'!$L$87:$L$101) -> 0 | E20: =SUMIF('OI 2015'!$I$87:$I$101,C20,'OI 2015'!$L$87:$L$101) -> 0 | F20: =SUMIF('OI 2016'!$I$87:$I$101,C20,'OI 2016'!$L$87:$L$101) -> 0 | G20: =SUMIF('OI 2017'!$I$112:$I$128,C20,'OI 2017'!$L$112:$L$128) -> 33 | H20: =SUMIF('OI 2018'!$I$112:$I$131,C20,'OI 2018'!$L$112:$L$131) -> 216 | I20: =SUMIF('OI 2019'!$I$113:$I$132,C20,'OI 2019'!$L$113:$L$132) -> 0 | J20: =SUMIF('OI 2020'!$I$144:$I$165,C20,'OI 2020'!$K$144:$K$165) -> 0 | K20: =SUMIF('OI 2021'!$I$145:$I$166,C20,'OI 2021'!$K$145:$K$166) -> 0 | L20: =SUMIF('OI 2022'!$I$158:$I$175,$C20,'OI 2022'!$K$158:$K$175) -> 0 | M20: =SUMIF('OI 2023'!$I$158:$I$173,$C20,'OI 2023'!$J$158:$J$173) -> 0
C21: V117-3.0MW | D21: =SUMIF('OI 2014'!$I$87:$I$101,C21,'OI 2014'!$L$87:$L$101) -> 6 | E21: =SUMIF('OI 2015'!$I$87:$I$101,C21,'OI 2015'!$L$87:$L$101) -> 0 | F21: =SUMIF('OI 2016'!$I$87:$I$101,C21,'OI 2016'!$L$87:$L$101) -> 0 | G21: =SUMIF('OI 2017'!$I$112:$I$128,C21,'OI 2017'!$L$112:$L$128) -> 0 | H21: =SUMIF('OI 2018'!$I$112:$I$131,C21,'OI 2018'!$L$112:$L$131) -> 0 | I21: =SUMIF('OI 2019'!$I$113:$I$132,C21,'OI 2019'!$L$113:$L$132) -> 0 | J21: =SUMIF('OI 2020'!$I$144:$I$165,C21,'OI 2020'!$K$144:$K$165) -> 0 | K21: =SUMIF('OI 2021'!$I$145:$I$166,C21,'OI 2021'!$K$145:$K$166) -> 0 | L21: =SUMIF('OI 2022'!$I$158:$I$175,$C21,'OI 2022'!$K$158:$K$175) -> 0 | M21: =SUMIF('OI 2023'!$I$158:$I$173,$C21,'OI 2023'!$J$158:$J$173) -> 0
C22: V117-3.3MW | D22: =SUMIF('OI 2014'!$I$87:$I$101,C22,'OI 2014'!$L$87:$L$101) -> 19 | E22: =SUMIF('OI 2015'!$I$87:$I$101,C22,'OI 2015'!$L$87:$L$101) -> 365.45455 | F22: =SUMIF('OI 2016'!$I$87:$I$101,C22,'OI 2016'!$L$87:$L$101) -> 53.939394 | G22: =SUMIF('OI 2017'!$I$112:$I$128,C22,'OI 2017'!$L$112:$L$128) -> 0 | H22: =SUMIF('OI 2018'!$I$112:$I$131,C22,'OI 2018'!$L$112:$L$131) -> 10 | I22: =SUMIF('OI 2019'!$I$113:$I$132,C22,'OI 2019'!$L$113:$L$132) -> 0 | J22: =SUMIF('OI 2020'!$I$144:$I$165,C22,'OI 2020'!$K$144:$K$165) -> 0 | K22: =SUMIF('OI 2021'!$I$145:$I$166,C22,'OI 2021'!$K$145:$K$166) -> 0 | L22: =SUMIF('OI 2022'!$I$158:$I$175,$C22,'OI 2022'!$K$158:$K$175) -> 0 | M22: =SUMIF('OI 2023'!$I$158:$I$173,$C22,'OI 2023'!$J$158:$J$173) -> 0
C23: V117-3.45MW | D23: =SUMIF('OI 2014'!$I$87:$I$101,C23,'OI 2014'!$L$87:$L$101) -> 0 | E23: =SUMIF('OI 2015'!$I$87:$I$101,C23,'OI 2015'!$L$87:$L$101) -> 30 | F23: =SUMIF('OI 2016'!$I$87:$I$101,C23,'OI 2016'!$L$87:$L$101) -> 398.97101 | G23: =SUMIF('OI 2017'!$I$112:$I$128,C23,'OI 2017'!$L$112:$L$128) -> 66.932367 | H23: =SUMIF('OI 2018'!$I$112:$I$131,C23,'OI 2018'!$L$112:$L$131) -> 178.15217 | I23: =SUMIF('OI 2019'!$I$113:$I$132,C23,'OI 2019'!$L$113:$L$132) -> 46 | J23: =SUMIF('OI 2020'!$I$144:$I$165,C23,'OI 2020'!$K$144:$K$165) -> 33 | K23: =SUMIF('OI 2021'!$I$145:$I$166,C23,'OI 2021'!$K$145:$K$166) -> 23 | L23: =SUMIF('OI 2022'!$I$158:$I$175,$C23,'OI 2022'!$K$158:$K$175) -> 13 | M23: =SUMIF('OI 2023'!$I$158:$I$173,$C23,'OI 2023'!$J$158:$J$173) -> 0
C24: V117-4.2MW | D24: =SUMIF('OI 2014'!$I$87:$I$101,C24,'OI 2014'!$L$87:$L$101) -> 0 | E24: =SUMIF('OI 2015'!$I$87:$I$101,C24,'OI 2015'!$L$87:$L$101) -> 0 | F24: =SUMIF('OI 2016'!$I$87:$I$101,C24,'OI 2016'!$L$87:$L$101) -> 0 | G24: =SUMIF('OI 2017'!$I$112:$I$128,C24,'OI 2017'!$L$112:$L$128) -> 0 | H24: =SUMIF('OI 2018'!$I$112:$I$131,C24,'OI 2018'!$L$112:$L$131) -> 31 | I24: =SUMIF('OI 2019'!$I$113:$I$132,C24,'OI 2019'!$L$113:$L$132) -> 107 | J24: =SUMIF('OI 2020'!$I$144:$I$165,C24,'OI 2020'!$K$144:$K$165) -> 166 | K24: =SUMIF('OI 2021'!$I$145:$I$166,C24,'OI 2021'!$K$145:$K$166) -> 97 | L24: =SUMIF('OI 2022'!$I$158:$I$175,$C24,'OI 2022'!$K$158:$K$175) -> 36 | M24: =SUMIF('OI 2023'!$I$158:$I$173,$C24,'OI 2023'!$J$158:$J$173) -> 44
... C31: V136-3.0MW | D31: =SUMIF('OI 2014'!$I$87:$I$101,C31,'OI 2014'!$L$87:$L$101) -> 0 | E31: =SUMIF('OI 2015'!$I$87:$I$101,C31,'OI 2015'!$L$87:$L$101) -> 0 | F31: =SUMIF('OI 2016'!$I$87:$I$101,C31,'OI 2016'!$L$87:$L$101) -> 0 | G31: =SUMIF('OI 2017'!$I$112:$I$128,C31,'OI 2017'!$L$112:$L$128) -> 60 | H31: =SUMIF('OI 2018'!$I$112:$I$131,C31,'OI 2018'!$L$112:$L$131) -> 0 | I31: =SUMIF('OI 2019'!$I$113:$I$132,C31,'OI 2019'!$L$113:$L$132) -> 0 | J31: =SUMIF('OI 2020'!$I$144:$I$165,C31,'OI 2020'!$K$144:$K$165) -> 0 | K31: =SUMIF('OI 2021'!$I$145:$I$166,C31,'OI 2021'!$K$145:$K$166) -> 0 | L31: =SUMIF('OI 2022'!$I$158:$I$175,$C31,'OI 2022'!$K$158:$K$175) -> 0 | M31: =SUMIF('OI 2023'!$I$158:$I$173,$C31,'OI 2023'!$J$158:$J$173) -> 0
C32: V136-3.45MW | D32: =SUMIF('OI 2014'!$I$87:$I$101,C32,'OI 2014'!$L$87:$L$101) -> 0 | E32: =SUMIF('OI 2015'!$I$87:$I$101,C32,'OI 2015'!$L$87:$L$101) -> 33.913043 | F32: =SUMIF('OI 2016'!$I$87:$I$101,C32,'OI 2016'!$L$87:$L$101) -> 0 | G32: =SUMIF('OI 2017'!$I$112:$I$128,C32,'OI 2017'!$L$112:$L$128) -> 634.8341 | H32: =SUMIF('OI 2018'!$I$112:$I$131,C32,'OI 2018'!$L$112:$L$131) -> 717.7179 | I32: =SUMIF('OI 2019'!$I$113:$I$132,C32,'OI 2019'!$L$113:$L$132) -> 114.88889 | J32: =SUMIF('OI 2020'!$I$144:$I$165,C32,'OI 2020'!$K$144:$K$165) -> 274 | K32: =SUMIF('OI 2021'!$I$145:$I$166,C32,'OI 2021'!$K$145:$K$166) -> 79 | L32: =SUMIF('OI 2022'!$I$158:$I$175,$C32,'OI 2022'!$K$158:$K$175) -> 11 | M32: =SUMIF('OI 2023'!$I$158:$I$173,$C32,'OI 2023'!$J$158:$J$173) -> 0 | Q32: Average length | R32: 2014 | S32: 2015 | T32: 2016 | U32: 2017 | V32: 2018 | W32: 2019 | X32: 2020 | Y32: 2021 | Z32: 2022 | AA32: 2023
C33: V136-3.6MW | D33: =SUMIF('OI 2014'!$I$87:$I$101,C33,'OI 2014'!$L$87:$L$101) -> 0 | E33: =SUMIF('OI 2015'!$I$87:$I$101,C33,'OI 2015'!$L$87:$L$101) -> 0 | F33: =SUMIF('OI 2016'!$I$87:$I$101,C33,'OI 2016'!$L$87:$L$101) -> 0 | G33: =SUMIF('OI 2017'!$I$112:$I$128,C33,'OI 2017'!$L$112:$L$128) -> 44.166667 | H33: =SUMIF('OI 2018'!$I$112:$I$131,C33,'OI 2018'!$L$112:$L$131) -> 103 | I33: =SUMIF('OI 2019'!$I$113:$I$132,C33,'OI 2019'!$L$113:$L$132) -> 12 | J33: =SUMIF('OI 2020'!$I$144:$I$165,C33,'OI 2020'!$K$144:$K$165) -> 1 | K33: =SUMIF('OI 2021'!$I$145:$I$166,C33,'OI 2021'!$K$145:$K$166) -> 0 | L33: =SUMIF('OI 2022'!$I$158:$I$175,$C33,'OI 2022'!$K$158:$K$175) -> 0 | M33: =SUMIF('OI 2023'!$I$158:$I$173,$C33,'OI 2023'!$J$158:$J$173) -> 0 | Q33: AOM4000 | R33: ='OI 2014'!G81 -> 7.7647059 | S33: ='OI 2015'!G81 -> 7.7931034 | T33: ='OI 2016'!G81 -> 10.24 | U33: ='OI 2017'!G106 -> 11.375 | V33: ='OI 2018'!G106 -> 10.214286 | W33: ='OI 2019'!G107 -> 13.571429 | X33: ='OI 2020'!G138 -> 12.75 | Y33: ='OI 2021'!G140 -> 18.125 | Z33: ='OI 2022'!G152 -> 14.5
C34: V136-4.2MW | D34: =SUMIF('OI 2014'!$I$87:$I$101,C34,'OI 2014'!$L$87:$L$101) -> 0 | E34: =SUMIF('OI 2015'!$I$87:$I$101,C34,'OI 2015'!$L$87:$L$101) -> 0 | F34: =SUMIF('OI 2016'!$I$87:$I$101,C34,'OI 2016'!$L$87:$L$101) -> 0 | G34: =SUMIF('OI 2017'!$I$112:$I$128,C34,'OI 2017'!$L$112:$L$128) -> 85 | H34: =SUMIF('OI 2018'!$I$112:$I$131,C34,'OI 2018'!$L$112:$L$131) -> 406.80952 | I34: =SUMIF('OI 2019'!$I$113:$I$132,C34,'OI 2019'!$L$113:$L$132) -> 237.9103 | J34: =SUMIF('OI 2020'!$I$144:$I$165,C34,'OI 2020'!$K$144:$K$165) -> 221 | K34: =SUMIF('OI 2021'!$I$145:$I$166,C34,'OI 2021'!$K$145:$K$166) -> 79 | L34: =SUMIF('OI 2022'!$I$158:$I$175,$C34,'OI 2022'!$K$158:$K$175) -> 63 | M34: =SUMIF('OI 2023'!$I$158:$I$173,$C34,'OI 2023'!$J$158:$J$173) -> 30 | Q34: AOM5000 | R34: ='OI 2014'!G80 -> 8.875 | S34: ='OI 2015'!G80 -> 10.029412 | T34: ='OI 2016'!G80 -> 10.2 | U34: ='OI 2017'!G105 -> 13.916667 | V34: ='OI 2018'!G105 -> 15.196078 | W34: ='OI 2019'!G106 -> 18.914894 | X34: ='OI 2020'!G137 -> 18.109589 | Y34: ='OI 2021'!G139 -> 18.886792 | Z34: ='OI 2022'!G151 -> 21.591837
C35: V136-4.5MW | D35: =SUMIF('OI 2014'!$I$87:$I$101,C35,'OI 2014'!$L$87:$L$101) -> 0 | E35: =SUMIF('OI 2015'!$I$87:$I$101,C35,'OI 2015'!$L$87:$L$101) -> 0 | F35: =SUMIF('OI 2016'!$I$87:$I$101,C35,'OI 2016'!$L$87:$L$101) -> 0 | G35: =SUMIF('OI 2017'!$I$112:$I$128,C35,'OI 2017'!$L$112:$L$128) -> 0 | H35: =SUMIF('OI 2018'!$I$112:$I$131,C35,'OI 2018'!$L$112:$L$131) -> 0 | I35: =SUMIF('OI 2019'!$I$113:$I$132,C35,'OI 2019'!$L$113:$L$132) -> 0 | J35: =SUMIF('OI 2020'!$I$144:$I$165,C35,'OI 2020'!$K$144:$K$165) -> 0 | K35: =SUMIF('OI 2021'!$I$145:$I$166,C35,'OI 2021'!$K$145:$K$166) -> 0 | L35: =SUMIF('OI 2022'!$I$158:$I$175,$C35,'OI 2022'!$K$158:$K$175) -> 116 | M35: =SUMIF('OI 2023'!$I$158:$I$173,$C35,'OI 2023'!$J$158:$J$173) -> 136
C36: V150-4.2MW | D36: =SUMIF('OI 2014'!$I$87:$I$101,C36,'OI 2014'!$L$87:$L$101) -> 0 | E36: =SUMIF('OI 2015'!$I$87:$I$101,C36,'OI 2015'!$L$87:$L$101) -> 0 | F36: =SUMIF('OI 2016'!$I$87:$I$101,C36,'OI 2016'!$L$87:$L$101) -> 0 | G36: =SUMIF('OI 2017'!$I$112:$I$128,C36,'OI 2017'!$L$112:$L$128) -> 0 | H36: =SUMIF('OI 2018'!$I$112:$I$131,C36,'OI 2018'!$L$112:$L$131) -> 267 | I36: =SUMIF('OI 2019'!$I$113:$I$132,C36,'OI 2019'!$L$113:$L$132) -> 1056.8571 | J36: =SUMIF('OI 2020'!$I$144:$I$165,C36,'OI 2020'!$K$144:$K$165) -> 1025.9048 | K36: =SUMIF('OI 2021'!$I$145:$I$166,C36,'OI 2021'!$K$145:$K$166) -> 520 | L36: =SUMIF('OI 2022'!$I$158:$I$175,$C36,'OI 2022'!$K$158:$K$175) -> 139 | M36: =SUMIF('OI 2023'!$I$158:$I$173,$C36,'OI 2023'!$J$158:$J$173) -> 223
C37: V150-4.3MW | D37: =SUMIF('OI 2014'!$I$87:$I$101,C37,'OI 2014'!$L$87:$L$101) -> 0 | E37: =SUMIF('OI 2015'!$I$87:$I$101,C37,'OI 2015'!$L$87:$L$101) -> 0 | F37: =SUMIF('OI 2016'!$I$87:$I$101,C37,'OI 2016'!$L$87:$L$101) -> 0 | G37: =SUMIF('OI 2017'!$I$112:$I$128,C37,'OI 2017'!$L$112:$L$128) -> 0 | H37: =SUMIF('OI 2018'!$I$112:$I$131,C37,'OI 2018'!$L$112:$L$131) -> 0 | I37: =SUMIF('OI 2019'!$I$113:$I$132,C37,'OI 2019'!$L$113:$L$132) -> 0 | J37: =SUMIF('OI 2020'!$I$144:$I$165,C37,'OI 2020'!$K$144:$K$165) -> 29 | K37: =SUMIF('OI 2021'!$I$145:$I$166,C37,'OI 2021'!$K$145:$K$166) -> 0 | L37: =SUMIF('OI 2022'!$I$158:$I$175,$C37,'OI 2022'!$K$158:$K$175) -> 0 | M37: =SUMIF('OI 2023'!$I$158:$I$173,$C37,'OI 2023'!$J$158:$J$173) -> 0
C38: V150-4.5MW | D38: =SUMIF('OI 2014'!$I$87:$I$101,C38,'OI 2014'!$L$87:$L$101) -> 0 | E38: =SUMIF('OI 2015'!$I$87:$I$101,C38,'OI 2015'!$L$87:$L$101) -> 0 | F38: =SUMIF('OI 2016'!$I$87:$I$101,C38,'OI 2016'!$L$87:$L$101) -> 0 | G38: =SUMIF('OI 2017'!$I$112:$I$128,C38,'OI 2017'!$L$112:$L$128) -> 0 | H38: =SUMIF('OI 2018'!$I$112:$I$131,C38,'OI 2018'!$L$112:$L$131) -> 0 | I38: =SUMIF('OI 2019'!$I$113:$I$132,C38,'OI 2019'!$L$113:$L$132) -> 0 | J38: =SUMIF('OI 2020'!$I$144:$I$165,C38,'OI 2020'!$K$144:$K$165) -> 91 | K38: =SUMIF('OI 2021'!$I$145:$I$166,C38,'OI 2021'!$K$145:$K$166) -> 257 | L38: =SUMIF('OI 2022'!$I$158:$I$175,$C38,'OI 2022'!$K$158:$K$175) -> 742 | M38: =SUMIF('OI 2023'!$I$158:$I$173,$C38,'OI 2023'!$J$158:$J$173) -> 668
C39: V150-5.6MW | D39: =SUMIF('OI 2014'!$I$87:$I$101,C39,'OI 2014'!$L$87:$L$101) -> 0 | E39: =SUMIF('OI 2015'!$I$87:$I$101,C39,'OI 2015'!$L$87:$L$101) -> 0 | F39: =SUMIF('OI 2016'!$I$87:$I$101,C39,'OI 2016'!$L$87:$L$101) -> 0 | G39: =SUMIF('OI 2017'!$I$112:$I$128,C39,'OI 2017'!$L$112:$L$128) -> 0 | H39: =SUMIF('OI 2018'!$I$112:$I$131,C39,'OI 2018'!$L$112:$L$131) -> 0 | I39: =SUMIF('OI 2019'!$I$113:$I$132,C39,'OI 2019'!$L$113:$L$132) -> 50.964286 | J39: =SUMIF('OI 2020'!$I$144:$I$165,C39,'OI 2020'!$K$144:$K$165) -> 22 | K39: =SUMIF('OI 2021'!$I$145:$I$166,C39,'OI 2021'!$K$145:$K$166) -> 7 | L39: =SUMIF('OI 2022'!$I$158:$I$175,$C39,'OI 2022'!$K$158:$K$175) -> 0 | M39: =SUMIF('OI 2023'!$I$158:$I$173,$C39,'OI 2023'!$J$158:$J$173) -> 1
C40: V155-3.3MW | D40: =SUMIF('OI 2014'!$I$87:$I$101,C40,'OI 2014'!$L$87:$L$101) -> 0 | E40: =SUMIF('OI 2015'!$I$87:$I$101,C40,'OI 2015'!$L$87:$L$101) -> 0 | F40: =SUMIF('OI 2016'!$I$87:$I$101,C40,'OI 2016'!$L$87:$L$101) -> 0 | G40: =SUMIF('OI 2017'!$I$112:$I$128,C40,'OI 2017'!$L$112:$L$128) -> 0 | H40: =SUMIF('OI 2018'!$I$112:$I$131,C40,'OI 2018'!$L$112:$L$131) -> 0 | I40: =SUMIF('OI 2019'!$I$113:$I$132,C40,'OI 2019'!$L$113:$L$132) -> 0 | J40: =SUMIF('OI 2020'!$I$144:$I$165,C40,'OI 2020'!$K$144:$K$165) -> 141 | K40: =SUMIF('OI 2021'!$I$145:$I$166,C40,'OI 2021'!$K$145:$K$166) -> 0 | L40: =SUMIF('OI 2022'!$I$158:$I$175,$C40,'OI 2022'!$K$158:$K$175) -> 0 | M40: =SUMIF('OI 2023'!$I$158:$I$173,$C40,'OI 2023'!$J$158:$J$173) -> 0
C41: V155-3.6MW | D41: =SUMIF('OI 2014'!$I$87:$I$101,C41,'OI 2014'!$L$87:$L$101) -> 0 | E41: =SUMIF('OI 2015'!$I$87:$I$101,C41,'OI 2015'!$L$87:$L$101) -> 0 | F41: =SUMIF('OI 2016'!$I$87:$I$101,C41,'OI 2016'!$L$87:$L$101) -> 0 | G41: =SUMIF('OI 2017'!$I$112:$I$128,C41,'OI 2017'!$L$112:$L$128) -> 0 | H41: =SUMIF('OI 2018'!$I$112:$I$131,C41,'OI 2018'!$L$112:$L$131) -> 0 | I41: =SUMIF('OI 2019'!$I$113:$I$132,C41,'OI 2019'!$L$113:$L$132) -> 0 | J41: =SUMIF('OI 2020'!$I$144:$I$165,C41,'OI 2020'!$K$144:$K$165) -> 0 | K41: =SUMIF('OI 2021'!$I$145:$I$166,C41,'OI 2021'!$K$145:$K$166) -> 0 | L41: =SUMIF('OI 2022'!$I$158:$I$175,$C41,'OI 2022'!$K$158:$K$175) -> 15 | M41: =SUMIF('OI 2023'!$I$158:$I$173,$C41,'OI 2023'!$J$158:$J$173) -> 36
C42: V162-5.6MW | D42: =SUMIF('OI 2014'!$I$87:$I$101,C42,'OI 2014'!$L$87:$L$101) -> 0 | E42: =SUMIF('OI 2015'!$I$87:$I$101,C42,'OI 2015'!$L$87:$L$101) -> 0 | F42: =SUMIF('OI 2016'!$I$87:$I$101,C42,'OI 2016'!$L$87:$L$101) -> 0 | G42: =SUMIF('OI 2017'!$I$112:$I$128,C42,'OI 2017'!$L$112:$L$128) -> 0 | H42: =SUMIF('OI 2018'!$I$112:$I$131,C42,'OI 2018'!$L$112:$L$131) -> 0 | I42: =SUMIF('OI 2019'!$I$113:$I$132,C42,'OI 2019'!$L$113:$L$132) -> 45 | J42: =SUMIF('OI 2020'!$I$144:$I$165,C42,'OI 2020'!$K$144:$K$165) -> 179 | K42: =SUMIF('OI 2021'!$I$145:$I$166,C42,'OI 2021'!$K$145:$K$166) -> 40 | L42: =SUMIF('OI 2022'!$I$158:$I$175,$C42,'OI 2022'!$K$158:$K$175) -> 0 | M42: =SUMIF('OI 2023'!$I$158:$I$173,$C42,'OI 2023'!$J$158:$J$173) -> 16
C43: V162-6.0MW | D43: =SUMIF('OI 2014'!$I$87:$I$101,C43,'OI 2014'!$L$87:$L$101) -> 0 | E43: =SUMIF('OI 2015'!$I$87:$I$101,C43,'OI 2015'!$L$87:$L$101) -> 0 | F43: =SUMIF('OI 2016'!$I$87:$I$101,C43,'OI 2016'!$L$87:$L$101) -> 0 | G43: =SUMIF('OI 2017'!$I$112:$I$128,C43,'OI 2017'!$L$112:$L$128) -> 0 | H43: =SUMIF('OI 2018'!$I$112:$I$131,C43,'OI 2018'!$L$112:$L$131) -> 0 | I43: =SUMIF('OI 2019'!$I$113:$I$132,C43,'OI 2019'!$L$113:$L$132) -> 0 | J43: =SUMIF('OI 2020'!$I$144:$I$165,C43,'OI 2020'!$K$144:$K$165) -> 38 | K43: =SUMIF('OI 2021'!$I$145:$I$166,C43,'OI 2021'!$K$145:$K$166) -> 303 | L43: =SUMIF('OI 2022'!$I$158:$I$175,$C43,'OI 2022'!$K$158:$K$175) -> 0 | M43: =SUMIF('OI 2023'!$I$158:$I$173,$C43,'OI 2023'!$J$158:$J$173) -> 0
C44: V162-6.2MW | D44: =SUMIF('OI 2014'!$I$87:$I$101,C44,'OI 2014'!$L$87:$L$101) -> 0 | E44: =SUMIF('OI 2015'!$I$87:$I$101,C44,'OI 2015'!$L$87:$L$101) -> 0 | F44: =SUMIF('OI 2016'!$I$87:$I$101,C44,'OI 2016'!$L$87:$L$101) -> 0 | G44: =SUMIF('OI 2017'!$I$112:$I$128,C44,'OI 2017'!$L$112:$L$128) -> 0 | H44: =SUMIF('OI 2018'!$I$112:$I$131,C44,'OI 2018'!$L$112:$L$131) -> 0 | I44: =SUMIF('OI 2019'!$I$113:$I$132,C44,'OI 2019'!$L$113:$L$132) -> 0 | J44: =SUMIF('OI 2020'!$I$144:$I$165,C44,'OI 2020'!$K$144:$K$165) -> 0 | K44: =SUMIF('OI 2021'!$I$145:$I$166,C44,'OI 2021'!$K$145:$K$166) -> 176 | L44: =SUMIF('OI 2022'!$I$158:$I$175,$C44,'OI 2022'!$K$158:$K$175) -> 392 | M44: =SUMIF('OI 2023'!$I$158:$I$173,$C44,'OI 2023'!$J$158:$J$173) -> 281
C45: V163-4.5MW | D45: =SUMIF('OI 2014'!$I$87:$I$101,C45,'OI 2014'!$L$87:$L$101) -> 0 | E45: =SUMIF('OI 2015'!$I$87:$I$101,C45,'OI 2015'!$L$87:$L$101) -> 0 | F45: =SUMIF('OI 2016'!$I$87:$I$101,C45,'OI 2016'!$L$87:$L$101) -> 0 | G45: =SUMIF('OI 2017'!$I$112:$I$128,C45,'OI 2017'!$L$112:$L$128) -> 0 | H45: =SUMIF('OI 2018'!$I$112:$I$131,C45,'OI 2018'!$L$112:$L$131) -> 0 | I45: =SUMIF('OI 2019'!$I$113:$I$132,C45,'OI 2019'!$L$113:$L$132) -> 0 | J45: =SUMIF('OI 2020'!$I$144:$I$165,C45,'OI 2020'!$K$144:$K$165) -> 0 | K45: =SUMIF('OI 2021'!$I$145:$I$166,C45,'OI 2021'!$K$145:$K$166) -> 0 | L45: =SUMIF('OI 2022'!$I$158:$I$175,$C45,'OI 2022'!$K$158:$K$175) -> 0 | M45: =SUMIF('OI 2023'!$I$158:$I$173,$C45,'OI 2023'!$J$158:$J$173) -> 960
C46: V164-10.0MW | D46: =SUMIF('OI 2014'!$I$87:$I$101,C46,'OI 2014'!$L$87:$L$101) -> 0 | E46: =SUMIF('OI 2015'!$I$87:$I$101,C46,'OI 2015'!$L$87:$L$101) -> 0 | F46: =SUMIF('OI 2016'!$I$87:$I$101,C46,'OI 2016'!$L$87:$L$101) -> 0 | G46: =SUMIF('OI 2017'!$I$112:$I$128,C46,'OI 2017'!$L$112:$L$128) -> 0 | H46: =SUMIF('OI 2018'!$I$112:$I$131,C46,'OI 2018'!$L$112:$L$131) -> 0 | I46: =SUMIF('OI 2019'!$I$113:$I$132,C46,'OI 2019'!$L$113:$L$132) -> 0 | J46: =SUMIF('OI 2020'!$I$144:$I$165,C46,'OI 2020'!$K$144:$K$165) -> 0 | K46: =SUMIF('OI 2021'!$I$145:$I$166,C46,'OI 2021'!$K$145:$K$166) -> 0 | L46: =SUMIF('OI 2022'!$I$158:$I$175,$C46,'OI 2022'!$K$158:$K$175) -> 6 | M46: =SUMIF('OI 2023'!$I$158:$I$173,$C46,'OI 2023'!$J$158:$J$173) -> 0
...

Sheet Market share
D6: 2026 | E6: 2025 | F6: 2024 | G6: 2023 | H6: 2022 | I6: 2021 | J6: 2020 | K6: 2019 | L6: 2018 | M6: 2017 | N6: 2016 | O6: 2015 | P6: 2014 | Q6: 2013 | R6: 2012 | S6: 2011
C7: AF | F7: ='OI 2024'!H233 -> 0.027769722 | G7: ='OI 2023'!H213 -> 0.035627742 | J7: ='OI 2020'!H218 -> 0.020171296
C8: AS | E8: ='OI 2025'!H236 -> 0.076372315 | F8: ='OI 2024'!H237 -> 0.0574971 | G8: ='OI 2023'!H217 -> 0.033204532 | H8: ='OI 2022'!H216 -> 0.10445845 | I8: ='OI 2021'!H216 -> 0.06116739 | J8: ='OI 2020'!H222 -> 0.201793
C9: AU | E9: ='OI 2025'!H238 -> 0.046269921 | F9: ='OI 2024'!H239 -> 0.094765081 | G9: ='OI 2023'!H219 -> 0.016635012 | H9: ='OI 2022'!H218 -> 0.13153595 | I9: ='OI 2021'!H217 -> 0.076410999 | J9: ='OI 2020'!H223 -> 0.057712319
C10: EU | E10: ='OI 2025'!H252 -> 0.49973054 | F10: ='OI 2024'!H255 -> 0.50442285 | G10: ='OI 2023'!H233 -> 0.37016177 | H10: ='OI 2022'!H233 -> 0.29190009 | I10: ='OI 2021'!H235 -> 0.45036179 | J10: ='OI 2020'!H238 -> 0.36156247
C11: NA | E11: ='OI 2025'!H256 -> 0.27946724 | F11: ='OI 2024'!H261 -> 0.33642691 | G11: ='OI 2023'!H235 -> 0.46250573 | H11: ='OI 2022'!H234 -> 0.21930439 | I11: ='OI 2021'!H238 -> 0.28760251 | J11: ='OI 2020'!H241 -> 0.19618987
C12: SA | E12: ='OI 2025'!H259 -> 0.098159982 | F12: ='OI 2024'!H263 -> 0.006888051 | G12: ='OI 2023'!H237 -> 0.11749296 | H12: ='OI 2022'!H236 -> 0.25280112 | I12: ='OI 2021'!H240 -> 0.12445731 | J12: ='OI 2020'!H244 -> 0.16257104

Sheet blade delivery
C1: turbines | G1: blades
B2: platform | C2: 2023 | D2: 2024 | E2: 2025 | G2: 2023 | H2: 2024 | I2: 2025
A3: =LEFT(B3,4) -> V100 | B3: V100-2.0MW | C3: =SUMIF(N$7:N$39,B3,P$7:P$39) -> 2 | D3: =SUMIF(T$7:T$39,B3,S$7:S$39) -> 0 | G3: =C3*3 -> 6 | H3: =D3*3 -> 0
A4: =LEFT(B4,4) -> V110 | B4: V110-2.2MW | C4: =SUMIF(N$7:N$39,B4,P$7:P$39) -> 33 | D4: =SUMIF(T$7:T$39,B4,S$7:S$39) -> 0 | G4: =C4*3 -> 99 | H4: =D4*3 -> 0
A5: =LEFT(B5,4) -> V117 | B5: V117-4.2MW | C5: =SUMIF(N$7:N$39,B5,P$7:P$39) -> 22 | D5: =SUMIF(T$7:T$39,B5,S$7:S$39) -> 12 | G5: =C5*3 -> 66 | H5: =D5*3 -> 36
A6: =LEFT(B6,4) -> V126 | B6: V126-3.45MW | C6: =SUMIF(N$7:N$39,B6,P$7:P$39) -> 11 | D6: =SUMIF(T$7:T$39,B6,S$7:S$39) -> 0 | G6: =C6*3 -> 33 | H6: =D6*3 -> 0 | P6: 2023 | S6: 2024
A7: =LEFT(B7,4) -> V136 | B7: V136-4.2MW | C7: =SUMIF(N$7:N$39,B7,P$7:P$39) -> 49 | D7: =SUMIF(T$7:T$39,B7,S$7:S$39) -> 0 | G7: =C7*3 -> 147 | H7: =D7*3 -> 0 | N7: V117-4.2MW | P7: 10 | S7: 43 | T7: V150-4.5MW
A8: =LEFT(B8,4) -> V136 | B8: V136-4.5MW | C8: =SUMIF(N$7:N$39,B8,P$7:P$39) -> 67 | D8: =SUMIF(T$7:T$39,B8,S$7:S$39) -> 0 | G8: =C8*3 -> 201 | H8: =D8*3 -> 0 | N8: V150-4.2MW | P8: 20 | S8: 31 | T8: V174-9.5MW
A9: =LEFT(B9,4) -> V150 | B9: V150-4.2MW | C9: =SUMIF(N$7:N$39,B9,P$7:P$39) -> 135 | D9: =SUMIF(T$7:T$39,B9,S$7:S$39) -> 0 | G9: =C9*3 -> 405 | H9: =D9*3 -> 0 | N9: V150-4.2MW | P9: 81 | S9: 94 | T9: V150-4.5MW
A10: =LEFT(B10,4) -> V150 | B10: V150-4.5MW | C10: =SUMIF(N$7:N$39,B10,P$7:P$39) -> 234 | D10: =SUMIF(T$7:T$39,B10,S$7:S$39) -> 276 | G10: =C10*3 -> 702 | H10: =D10*3 -> 828 | N10: V174-9.5MW | P10: 50 | S10: 3 | T10: V164-10.0MW
A11: =LEFT(B11,4) -> V162 | B11: V162-6.0MW | C11: =SUMIF(N$7:N$39,B11,P$7:P$39) -> 7 | D11: =SUMIF(T$7:T$39,B11,S$7:S$39) -> 0 | G11: =C11*3 -> 21 | H11: =D11*3 -> 0 | N11: V150-4.5MW | P11: 22 | S11: 19 | T11: V150-4.5MW
A12: =LEFT(B12,4) -> V162 | B12: V162-6.2MW | C12: =SUMIF(N$7:N$39,B12,P$7:P$39) -> 53 | D12: =SUMIF(T$7:T$39,B12,S$7:S$39) -> 12 | G12: =C12*3 -> 159 | H12: =D12*3 -> 36 | N12: V162-6.0MW | P12: 7 | S12: 120 | T12: V150-4.5MW
A13: =LEFT(B13,4) -> V164 | B13: V164-10.0MW | C13: =SUMIF(N$7:N$39,B13,P$7:P$39) -> 0 | D13: =SUMIF(T$7:T$39,B13,S$7:S$39) -> 3 | G13: =C13*3 -> 0 | H13: =D13*3 -> 9 | N13: V150-4.5MW | P13: 25 | S13: 12 | T13: V117-4.2MW
A14: =LEFT(B14,4) -> V174 | B14: V174-9.5MW | C14: =SUMIF(N$7:N$39,B14,P$7:P$39) -> 81 | D14: =SUMIF(T$7:T$39,B14,S$7:S$39) -> 31 | G14: =C14*3 -> 243 | H14: =D14*3 -> 93 | N14: V150-4.5MW | P14: 55 | S14: 12 | T14: V162-6.2MW
N15: V136-4.2MW | P15: 5
N16: V150-4.5MW | P16: 7
N17: V150-4.5MW | P17: 19
N18: V150-4.2MW | P18: 7
C19: turbines | G19: blades | N19: V117-4.2MW | P19: 12
C20: 2023 | D20: 2024 | E20: 2025 | G20: 2023 | H20: 2024 | I20: 2025 | N20: V150-4.2MW | P20: 18
B21: V100 | C21: =SUMIF(A$3:A$14,B21,C$3:C$14) -> 2 | D21: =SUMIF(A$3:A$14,B21,D$3:D$14) -> 0 | G21: =C21*3 -> 6 | H21: =D21*3 -> 0 | N21: V162-6.2MW | P21: 15
B22: V110 | C22: =SUMIF(A$3:A$14,B22,C$3:C$14) -> 33 | D22: =SUMIF(A$3:A$14,B22,D$3:D$14) -> 0 | G22: =C22*3 -> 99 | H22: =D22*3 -> 0 | N22: V136-4.5MW | P22: 8
B23: V117 | C23: =SUMIF(A$3:A$14,B23,C$3:C$14) -> 22 | D23: =SUMIF(A$3:A$14,B23,D$3:D$14) -> 12 | G23: =C23*3 -> 66 | H23: =D23*3 -> 36 | N23: V136-4.2MW | P23: 3
B24: V126 | C24: =SUMIF(A$3:A$14,B24,C$3:C$14) -> 11 | D24: =SUMIF(A$3:A$14,B24,D$3:D$14) -> 0 | G24: =C24*3 -> 33 | H24: =D24*3 -> 0 | N24: V174-9.5MW | P24: 31
B25: V136 | C25: =SUMIF(A$3:A$14,B25,C$3:C$14) -> 116 | D25: =SUMIF(A$3:A$14,B25,D$3:D$14) -> 0 | G25: =C25*3 -> 348 | H25: =D25*3 -> 0 | N25: V136-4.2MW | P25: 24
B26: V150 | C26: =SUMIF(A$3:A$14,B26,C$3:C$14) -> 369 | D26: =SUMIF(A$3:A$14,B26,D$3:D$14) -> 276 | G26: =C26*3 -> 1107 | H26: =D26*3 -> 828 | N26: V110-2.2MW | P26: 33
B27: V162 | C27: =SUMIF(A$3:A$14,B27,C$3:C$14) -> 60 | D27: =SUMIF(A$3:A$14,B27,D$3:D$14) -> 12 | G27: =C27*3 -> 180 | H27: =D27*3 -> 36 | N27: V150-4.5MW | P27: 19
B28: V164 | C28: =SUMIF(A$3:A$14,B28,C$3:C$14) -> 0 | D28: =SUMIF(A$3:A$14,B28,D$3:D$14) -> 3 | G28: =C28*3 -> 0 | H28: =D28*3 -> 9 | N28: V150-4.2MW | P28: 9
B29: V174 | C29: =SUMIF(A$3:A$14,B29,C$3:C$14) -> 81 | D29: =SUMIF(A$3:A$14,B29,D$3:D$14) -> 31 | G29: =C29*3 -> 243 | H29: =D29*3 -> 93 | N29: V162-6.2MW | P29: 15
N30: V126-3.45MW | P30: 11
N31: V136-4.2MW | P31: 7
N32: V100-2.0MW | P32: 2
N33: V136-4.5MW | P33: 59
N34: V136-4.2MW | P34: 10
N35: V150-4.5MW | P35: 23
N36: V150-4.5MW | P36: 23
N37: V162-6.2MW | P37: 11
N38: V150-4.5MW | P38: 41
N39: V162-6.2MW | P39: 12

Sheet delivery 2024
B1: date | C1: country | D1: size [MW] | E1: Service scheme | F1: Service time [years] | G1: customer | H1: # | I1: platform | J1: Rotor | K1: MW | L1: special mode | M1: Tower height | N1: Multi towerH | O1: # | P1: Multi platform | Q1: Rotor | R1: MW | S1: special mode | T1: Tower height | U1: # | V1: Multi platform | W1: Rotor | X1: MW | Z1: Note | AA1: delivery q | AB1: delivery y | AC1: platform check | AD1: country check
B3: 30.06.2021 | C3: Germany | D3: 476 | E3: offshore | F3: 10 | G3: Iberdrola | H3: 50 | I3: V174-9.5MW | J3: 174 | K3: 9.5 | Z3: offshore 75km from shore | AB3: 2024 | AC3: =COUNTIF($I$146:$I$176,I3) -> 0 | AD3: =COUNTIF($C$145:$C$176,C3) -> 0 | AF3: project complete
B4: 08.03.2022 | C4: Brazil | D4: 194 | E4: AOM5000 | F4: 5 | H4: 43 | I4: V150-4.5MW | J4: 150 | K4: 4.5 | AH4: 2024 | AI4: 1 | AJ4: 1
B5: 31.03.2022 | C5: Taiwan | D5: 295 | E5: AOM5000 | F5: 15 | G5: CIP | H5: 31 | I5: V174-9.5MW | J5: 174 | K5: 9.5 | AG5: 1 | AH5: 2024 | AI5: 1 | AJ5: 1 | AM5: 33 | AN5: V110-2.2MW
B6: 05.05.2022 | C6: Brazil | D6: 423 | E6: AOM5000 | F6: 20 | G6: Pan American Energy Energias Renováveis | H6: 94 | I6: V150-4.5MW | J6: 150 | K6: 4.5 | AH6: 2024 | AI6: 1 | AJ6: 1 | AM6: 7 | AN6: V136-4.2MW
B7: 27.06.2022 | C7: France | D7: 30 | E7: AOM5000 | F7: 15 | G7: Qair, TotalEnergies, BW Ideol | H7: 3 | I7: V164-10.0MW | J7: 164 | K7: 10 | AF7: 18 km offshore | AG7: 3 | AH7: 2024 | AI7: 1 | AJ7: 1 | AM7: 10 | AN7: V136-4.2MW
B8: 30.06.2022 | C8: Brazil | D8: 86 | E8: AOM5000 | F8: 25 | G8: PEC Energia | H8: 19 | I8: V150-4.5MW | J8: 150 | K8: 4.5 | AH8: 2024 | AI8: 1 | AJ8: 1 | AM8: 12 | AN8: V162-6.2MW
B9: 30.06.2022 | C9: UK | D9: 67 | E9: AOM5000 | G9: Red Rock Power limited | H9: 13 | I9: V136-4.5MW | J9: 136 | K9: 4.5 | O9: 2 | P9: V117-4.2MW | Q9: 117 | R9: 4.2 | AG9: 1 | AH9: 2024 | AI9: 1 | AJ9: 1
B10: 30.09.2022 | C10: Brazil | D10: 540 | E10: AOM5000 | F10: 25 | G10: ENGIE | H10: 120 | I10: V150-4.5MW | J10: 150 | K10: 4.5 | AG10: 3 | AH10: 2024 | AI10: 1 | AJ10: 1
B11: 30.09.2022 | C11: Japan | D11: 50 | E11: AOM5000 | F11: 20 | G11: Toda Corporation | H11: 12 | I11: V117-4.2MW | J11: 117 | K11: 4.2 | M11: 9x 114 + 3x84 | AG11: 2 | AH11: 2024 | AI11: 1 | AJ11: 1
B12: 30.09.2022 | C12: Finland | D12: 74 | E12: AOM5000 | F12: 30 | H12: 12 | I12: V162-6.2MW | J12: 162 | K12: 6.2 | AG12: 2 | AH12: 2024 | AI12: 1 | AJ12: 1
B20: region | C20: coutry | D20: Size MW
B21: AS | C21: Japan | D21: =SUMIF(C$2:C$13,C21,D$2:D$13) -> 50
B22: AS | C22: Taiwan | D22: =SUMIF(C$2:C$13,C22,D$2:D$13) -> 295
B23: EU | C23: Finland | D23: =SUMIF(C$2:C$13,C23,D$2:D$13) -> 74 | F23: =SQRT(D23)/5 -> 1.7204651
B24: EU | C24: France | D24: =SUMIF(C$2:C$13,C24,D$2:D$13) -> 30 | F24: =SQRT(D24)/5 -> 1.0954451
B25: EU | C25: Germany | D25: =SUMIF(C$2:C$13,C25,D$2:D$13) -> 476 | F25: =SQRT(D25)/5 -> 4.3634848
B26: EU | C26: UK | D26: =SUMIF(C$2:C$13,C26,D$2:D$13) -> 67 | F26: =SQRT(D26)/5 -> 1.6370706
B27: SA | C27: Brazil | D27: =SUMIF(C$2:C$13,C27,D$2:D$13) -> 1243

Sheet delivery 2023
B1: date | C1: country | D1: size [MW] | E1: Service scheme | F1: Service time [years] | G1: customer | H1: # | I1: platform | J1: Rotor | K1: MW | L1: special mode | M1: Tower height | N1: Multi towerH | O1: # | P1: Multi platform | Q1: Rotor | R1: MW | S1: special mode | T1: Tower height | U1: # | V1: Multi platform | W1: Rotor | X1: MW | Z1: Note | AA1: delivery q | AB1: delivery y | AC1: platform check | AD1: country check
B3: 31.03.2021 | C3: Ireland | D3: 30 | E3: AOM5000 | H3: 7 | I3: V117-4.2MW | J3: 117 | K3: 4.3 | L3: opt 4.3MW | M3: 76.5 | AA3: 2 | AB3: 2023 | AC3: 1 | AD3: 1
B4: 31.03.2021 | C4: Japan | D4: 42 | E4: AOM5000 | F4: 20 | G4: Toko Electrical Construction Co., Ltd | H4: 10 | I4: V117-4.2MW | J4: 117 | K4: 4.2 | L4: opt 4.2MW | M4: 94 | AA4: 1 | AB4: 2023 | AC4: 1 | AD4: 1 | AK4: 2023
B5: 03.05.2021 | C5: Sweden | D5: 86 | E5: AOM5000 | F5: 30 | G5: OX2 | H5: 20 | I5: V150-4.2MW | J5: 150 | K5: 4.3 | L5: opt 4.3MW | AA5: 2 | AB5: 2023 | AC5: 1 | AD5: 1 | AI5: V150-4.5MW | AK5: 25
B6: 16.06.2021 | C6: Brazil | D6: 348 | E6: AOM5000 | F6: 5 | H6: 81 | I6: V150-4.2MW | J6: 150 | K6: 4.3 | L6: opt 4.3MW | AB6: 2023 | AC6: 1 | AD6: 1
B7: 30.09.2021 | C7: Brazil | D7: 189 | E7: AOM5000 | F7: 20 | G7: Casa dos Ventos | H7: 42 | I7: V150-4.2MW | J7: 150 | K7: 4.5 | L7: opt 4.5MW | AA7: 3 | AB7: 2023 | AC7: 1 | AD7: 1
B8: 07.12.2021 | C8: Brazil | D8: 99 | E8: AOM5000 | F8: 15 | H8: 22 | I8: V150-4.5MW | J8: 150 | K8: 4.5 | AB8: 2023 | AC8: 1 | AD8: 1
B9: 29.12.2021 | C9: Finland | D9: 87 | E9: AOM5000 | F9: 25 | G9: ABO Wind AG | H9: 14 | I9: V162-6.2MW | J9: 162 | K9: 6.2 | AA9: 2 | AB9: 2023 | AC9: 1 | AD9: 1
B10: 30.12.2021 | C10: Germany | D10: 42 | E10: AOM4000 | F10: 20 | G10: Repowering Wöhrden Poolgesellschaft GmbH & Co KG | H10: 7 | I10: V162-6.0MW | J10: 162 | K10: 6 | AA10: 1 | AB10: 2023 | AC10: 1 | AD10: 1
B11: 31.12.2021 | C11: Brazil | D11: 113 | E11: AOM5000 | F11: 15 | H11: 25 | I11: V150-4.5MW | J11: 150 | K11: 4.5 | AA11: 2 | AB11: 2023 | AC11: 1 | AD11: 1
B12: 31.12.2021 | C12: Brazil | D12: 248 | E12: AOM5000 | F12: 20 | G12: Elera Renováveis | H12: 55 | I12: V150-4.5MW | J12: 150 | K12: 4.5 | AA12: 2 | AB12: 2023 | AC12: 1 | AD12: 1
B13: 03.03.2022 | C13: Estonia | D13: 21 | E13: AOM5000 | F13: 30 | G13: Enefit Green | H13: 5 | I13: V136-4.2MW | J13: 136 | K13: 4.2 | M13: 82 | AG13: 1 | AH13: 2023 | AI13: 1 | AJ13: 1
B14: 11.03.2022 | C14: Sweden | D14: 32 | E14: AOM5000 | F14: long-term | G14: Octopus Renewables | H14: 7 | I14: V150-4.5MW | J14: 150 | K14: 4.5 | AG14: 2 | AH14: 2023 | AI14: 1 | AJ14: 1
B15: 15.03.2022 | C15: Argentina | D15: 86 | E15: AOM5000 | F15: 30 | G15: PCR | H15: 19 | I15: V150-4.5MW | J15: 150 | K15: 4.5 | AG15: 1 | AH15: 2023 | AI15: 1 | AJ15: 1
B16: 18.03.2022 | C16: Italy | D16: 30 | E16: AOM5000 | F16: 15 | H16: 7 | I16: V150-4.2MW | J16: 150 | K16: 4.3 | L16: opt 4.3MW | AG16: 3 | AH16: 2023 | AI16: 1 | AJ16: 1
B17: 31.03.2022 | C17: Italy | D17: 97 | E17: AOM5000 | F17: multi-year | G17: ERG | H17: 12 | I17: V117-4.2MW | J17: 117 | K17: 4.2 | O17: 13 | P17: V117-3.45MW | Q17: 117 | R17: 3.45 | S17: opt 3.6MW | AG17: 1 | AH17: 2023 | AI17: 1 | AJ17: 1 | AM17: 7 | AN17: V150-4.2MW | AP17: 3 | AQ17: V164-10.0MW
B18: 31.03.2022 | C18: Australia | D18: 76 | H18: 18 | I18: V150-4.2MW | J18: 150 | K18: 4.2 | AG18: 1 | AH18: 2023 | AI18: 1 | AJ18: 1 | AM18: 12 | AN18: V117-4.2MW | AP18: 19 | AQ18: V150-4.5MW
B19: 31.03.2022 | C19: Finland | D19: 93 | E19: AOM5000 | F19: 30 | H19: 15 | I19: V162-6.2MW | J19: 162 | K19: 6.2 | AG19: 2 | AH19: 2023 | AI19: 1 | AJ19: 1 | AM19: 18 | AN19: V150-4.2MW | AP19: 120 | AQ19: V150-4.5MW
B20: 31.03.2022 | C20: Greece | D20: 36 | E20: AOM5000 | F20: 20 | H20: 8 | I20: V136-4.5MW | J20: 136 | K20: 4.5 | AG20: 2 | AH20: 2023 | AI20: 1 | AJ20: 1 | AM20: 15 | AN20: V162-6.2MW | AP20: 12 | AQ20: V117-4.2MW
B21: 31.03.2022 | C21: Italy | D21: 30 | E21: AOM4000 | F21: 10 | G21: A2A | H21: 3 | I21: V136-4.2MW | J21: 136 | K21: 4.2 | L21: opt 4.0MW | O21: 5 | P21: V136-3.45MW | Q21: 136 | R21: 3.6 | S21: Opt 3.6MW | AG21: 1 | AH21: 2023 | AI21: 1 | AJ21: 1 | AM21: 8 | AN21: V136-4.5MW | AP21: 12 | AQ21: V162-6.2MW
B22: 31.03.2022 | C22: Taiwan | D22: 295 | E22: offshore | F22: 14 | G22: Foxwell Energy Corp | H22: 31 | I22: V174-9.5MW | J22: 174 | K22: 9.5 | AG22: 1 | AH22: 2023 | AI22: 1 | AJ22: 1 | AM22: 24 | AN22: V136-4.2MW
B23: 08.06.2022 | C23: Italy | D23: 101 | E23: AOM5000 | G23: ERG | H23: 24 | I23: V136-4.2MW | J23: 136 | K23: 4.2 | AG23: 2 | AH23: 2023 | AI23: 1 | AJ23: 1 | AM23: 59 | AN23: V136-4.5MW
B24: 28.06.2022 | C24: Poland | D24: 73 | E24: AOM5000 | F24: 15 | G24: PAK-Polska Czysta Energia | H24: 33 | I24: V110-2.2MW | J24: 110 | K24: 2.2 | M24: 120 | AG24: 3 | AH24: 2023 | AI24: 1 | AJ24: 1 | AM24: 23 | AN24: V150-4.5MW
B25: 29.06.2022 | C25: United states | D25: 86 | E25: AOM5000 | F25: 10 | G25: Sacramento Municipal Unitility District | H25: 19 | I25: V150-4.5MW | J25: 150 | K25: 4.5 | AG25: 4 | AH25: 2023 | AI25: 1 | AJ25: 1 | AM25: 23 | AN25: V150-4.5MW
B26: 29.06.2022 | C26: Estonia | D26: 39 | E26: AOM5000 | F26: 30 | G26: Utilitas | H26: 9 | I26: V150-4.2MW | J26: 150 | K26: 4.3 | L26: opt 4.3MW | AG26: 2 | AH26: 2023 | AI26: 1 | AJ26: 1 | AM26: 11 | AN26: V162-6.2MW
B27: 29.06.2022 | C27: Finland | D27: 135 | E27: AOM5000 | F27: 35 | G27: Ilmatar Energy Oy | H27: 15 | I27: V162-6.2MW | J27: 162 | K27: 6.2 | O27: 10 | P27: V150-4.2MW | Q27: 150 | R27: 4.2 | Z27: # of turbines are assumed | AG27: 2 | AH27: 2023 | AI27: 1 | AJ27: 1 | AM27: 41 | AN27: V150-4.5MW
B28: 30.06.2022 | C28: Denmark | D28: 40 | E28: AOM5000 | F28: 20 | G28: Eurowind Energy | H28: 11 | I28: V126-3.45MW | J28: 126 | K28: 3.6 | L28: opt 3.6MW | AG28: 2 | AH28: 2023 | AI28: 1 | AJ28: 1
B29: 30.06.2022 | C29: Italy | D29: 39 | E29: AOM5000 | F29: 20 | G29: PLT engineering | H29: 7 | I29: V136-4.2MW | J29: 136 | K29: 4.3 | L29: opt 4.3MW | O29: 2 | P29: V117-4.2MW | Q29: 117 | R29: 4.2 | S29: opt 4.3MW | AG29: 2 | AH29: 2023 | AI29: 1 | AJ29: 1
B30: 30.06.2022 | C30: Italy | D30: 27 | E30: AOM4000 | F30: 10 | G30: IVPC | H30: 2 | I30: V100-2.0MW | J30: 100 | K30: 2.2 | L30: opt 2.2MW | O30: 6 | P30: V126-3.45MW | Q30: 126 | R30: 3.8 | S30: opt 3.8MW | AG30: 1 | AH30: 2023 | AI30: 1 | AJ30: 1
B31: 30.06.2022 | C31: United states | D31: 266 | E31: AOM5000 | F31: 30 | G31: Omega Energia | H31: 59 | I31: V136-4.5MW | J31: 136 | K31: 4.5 | AG31: 2 | AH31: 2023 | AI31: 1 | AJ31: 1
B32: 14.09.2022 | C32: New Zealand | D32: 43 | E32: AOM5000 | F32: 30 | G32: Mercury | H32: 10 | I32: V136-4.2MW | J32: 136 | K32: 4.3 | L32: opt 4.3MW | AG32: 2 | AH32: 2023 | AI32: 1 | AJ32: 1
B33: 19.09.2022 | C33: Spain | D33: 104 | E33: AOM4000 | F33: 10 | G33: Estudios y Proyectos Pradamap | H33: 23 | I33: V150-4.5MW | J33: 150 | K33: 4.5 | AH33: 2023 | AI33: 1 | AJ33: 1
B34: 21.09.2022 | C34: Brazil | D34: 104 | E34: AOM5000 | F34: 20 | G34: Polimix Energia | H34: 23 | I34: V150-4.5MW | J34: 150 | K34: 4.5 | AG34: 4 | AH34: 2023 | AI34: 1 | AJ34: 1
B35: 26.09.2022 | C35: Germany | D35: 66 | E35: AOM5000 | F35: 25 | G35: Gaarz IV Windkraft | H35: 11 | I35: V162-6.2MW | J35: 162 | K35: 6 | L35: opt 6.0MW | AG35: 3 | AH35: 2023 | AI35: 1 | AJ35: 1
B36: 29.09.2022 | C36: United states | D36: 185 | E36: AOM5000 | H36: 41 | I36: V150-4.5MW | J36: 150 | K36: 4.5 | AG36: 3 | AH36: 2023 | AI36: 1 | AJ36: 1
B37: 30.09.2022 | C37: Lithuania | D37: 74 | E37: AOM5000 | F37: 35 | G37: Vestas | H37: 12 | I37: V162-6.2MW | J37: 162 | K37: 6.2 | AF37: vestas EPC | AG37: 2 | AH37: 2023 | AI37: 1 | AJ37: 1
B38: 09.11.2022 | C38: United states | D38: 300 | E38: AOM5000 | F38: 10 | G38: Apex Clean Energy | H38: 50 | I38: V162-6.2MW | J38: 162 | K38: 6 | L38: opt 6.0MW | AG38: 3 | AH38: 2023 | AI38: 1 | AJ38: 1
B46: region | C46: coutry | D46: Size MW
B47: AS | C47: Japan | D47: =SUMIF(C$2:C$38,C47,D$2:D$38) -> 42
